{"message": "Not Found: /", "status_code": 404, "request": "<WSGIRequest: GET '/'>"}
{"message": "Method Not Allowed: /api/", "status_code": 405, "request": "<WSGIRequest: GET '/api/'>"}
{"message": "Method Not Allowed: /api/", "status_code": 405, "request": "<WSGIRequest: GET '/api/'>"}
{"message": "Not Found: /api/valid", "status_code": 404, "request": "<WSGIRequest: GET '/api/valid'>"}
{"message": "Method Not Allowed: /api/subdomain", "status_code": 405, "request": "<WSGIRequest: GET '/api/subdomain'>"}
{"message": "Internal Server Error: /api/subdomain", "exc_info": "Traceback (most recent call last):\n  File \"/venv/lib/python3.6/site-packages/django/core/handlers/exception.py\", line 34, in inner\n    response = get_response(request)\n  File \"/venv/lib/python3.6/site-packages/django/utils/deprecation.py\", line 90, in __call__\n    response = self.process_request(request)\n  File \"/venv/lib/python3.6/site-packages/django/middleware/common.py\", line 52, in process_request\n    if self.should_redirect_with_slash(request):\n  File \"/venv/lib/python3.6/site-packages/django/middleware/common.py\", line 70, in should_redirect_with_slash\n    not is_valid_path(request.path_info, urlconf) and\n  File \"/venv/lib/python3.6/site-packages/django/urls/base.py\", line 157, in is_valid_path\n    resolve(path, urlconf)\n  File \"/venv/lib/python3.6/site-packages/django/urls/base.py\", line 24, in resolve\n    return get_resolver(urlconf).resolve(path)\n  File \"/venv/lib/python3.6/site-packages/django/urls/resolvers.py\", line 491, in resolve\n    for pattern in self.url_patterns:\n  File \"/venv/lib/python3.6/site-packages/django/utils/functional.py\", line 37, in __get__\n    res = instance.__dict__[self.name] = self.func(instance)\n  File \"/venv/lib/python3.6/site-packages/django/urls/resolvers.py\", line 533, in url_patterns\n    patterns = getattr(self.urlconf_module, \"urlpatterns\", self.urlconf_module)\n  File \"/venv/lib/python3.6/site-packages/django/utils/functional.py\", line 37, in __get__\n    res = instance.__dict__[self.name] = self.func(instance)\n  File \"/venv/lib/python3.6/site-packages/django/urls/resolvers.py\", line 526, in urlconf_module\n    return import_module(self.urlconf_name)\n  File \"/usr/local/lib/python3.6/importlib/__init__.py\", line 126, in import_module\n    return _bootstrap._gcd_import(name[level:], package, level)\n  File \"<frozen importlib._bootstrap>\", line 994, in _gcd_import\n  File \"<frozen importlib._bootstrap>\", line 971, in _find_and_load\n  File \"<frozen importlib._bootstrap>\", line 955, in _find_and_load_unlocked\n  File \"<frozen importlib._bootstrap>\", line 665, in _load_unlocked\n  File \"<frozen importlib._bootstrap_external>\", line 678, in exec_module\n  File \"<frozen importlib._bootstrap>\", line 219, in _call_with_frames_removed\n  File \"/code/config/urls.py\", line 24, in <module>\n    url(r'^api/', include('api.urls')),\n  File \"/venv/lib/python3.6/site-packages/django/urls/conf.py\", line 34, in include\n    urlconf_module = import_module(urlconf_module)\n  File \"/usr/local/lib/python3.6/importlib/__init__.py\", line 126, in import_module\n    return _bootstrap._gcd_import(name[level:], package, level)\n  File \"<frozen importlib._bootstrap>\", line 994, in _gcd_import\n  File \"<frozen importlib._bootstrap>\", line 971, in _find_and_load\n  File \"<frozen importlib._bootstrap>\", line 955, in _find_and_load_unlocked\n  File \"<frozen importlib._bootstrap>\", line 665, in _load_unlocked\n  File \"<frozen importlib._bootstrap_external>\", line 678, in exec_module\n  File \"<frozen importlib._bootstrap>\", line 219, in _call_with_frames_removed\n  File \"/code/api/urls.py\", line 3, in <module>\n    from .views import ValidDomainIPView\n  File \"/code/api/views.py\", line 4, in <module>\n    import utlity\nModuleNotFoundError: No module named 'utlity'", "status_code": 500, "request": "<WSGIRequest: GET '/api/subdomain'>"}
{"message": "Internal Server Error: /api/subdomain", "exc_info": "Traceback (most recent call last):\n  File \"/venv/lib/python3.6/site-packages/django/core/handlers/exception.py\", line 34, in inner\n    response = get_response(request)\n  File \"/venv/lib/python3.6/site-packages/django/utils/deprecation.py\", line 90, in __call__\n    response = self.process_request(request)\n  File \"/venv/lib/python3.6/site-packages/django/middleware/common.py\", line 52, in process_request\n    if self.should_redirect_with_slash(request):\n  File \"/venv/lib/python3.6/site-packages/django/middleware/common.py\", line 70, in should_redirect_with_slash\n    not is_valid_path(request.path_info, urlconf) and\n  File \"/venv/lib/python3.6/site-packages/django/urls/base.py\", line 157, in is_valid_path\n    resolve(path, urlconf)\n  File \"/venv/lib/python3.6/site-packages/django/urls/base.py\", line 24, in resolve\n    return get_resolver(urlconf).resolve(path)\n  File \"/venv/lib/python3.6/site-packages/django/urls/resolvers.py\", line 491, in resolve\n    for pattern in self.url_patterns:\n  File \"/venv/lib/python3.6/site-packages/django/utils/functional.py\", line 37, in __get__\n    res = instance.__dict__[self.name] = self.func(instance)\n  File \"/venv/lib/python3.6/site-packages/django/urls/resolvers.py\", line 533, in url_patterns\n    patterns = getattr(self.urlconf_module, \"urlpatterns\", self.urlconf_module)\n  File \"/venv/lib/python3.6/site-packages/django/utils/functional.py\", line 37, in __get__\n    res = instance.__dict__[self.name] = self.func(instance)\n  File \"/venv/lib/python3.6/site-packages/django/urls/resolvers.py\", line 526, in urlconf_module\n    return import_module(self.urlconf_name)\n  File \"/usr/local/lib/python3.6/importlib/__init__.py\", line 126, in import_module\n    return _bootstrap._gcd_import(name[level:], package, level)\n  File \"<frozen importlib._bootstrap>\", line 994, in _gcd_import\n  File \"<frozen importlib._bootstrap>\", line 971, in _find_and_load\n  File \"<frozen importlib._bootstrap>\", line 955, in _find_and_load_unlocked\n  File \"<frozen importlib._bootstrap>\", line 665, in _load_unlocked\n  File \"<frozen importlib._bootstrap_external>\", line 678, in exec_module\n  File \"<frozen importlib._bootstrap>\", line 219, in _call_with_frames_removed\n  File \"/code/config/urls.py\", line 24, in <module>\n    url(r'^api/', include('api.urls')),\n  File \"/venv/lib/python3.6/site-packages/django/urls/conf.py\", line 34, in include\n    urlconf_module = import_module(urlconf_module)\n  File \"/usr/local/lib/python3.6/importlib/__init__.py\", line 126, in import_module\n    return _bootstrap._gcd_import(name[level:], package, level)\n  File \"<frozen importlib._bootstrap>\", line 994, in _gcd_import\n  File \"<frozen importlib._bootstrap>\", line 971, in _find_and_load\n  File \"<frozen importlib._bootstrap>\", line 955, in _find_and_load_unlocked\n  File \"<frozen importlib._bootstrap>\", line 665, in _load_unlocked\n  File \"<frozen importlib._bootstrap_external>\", line 678, in exec_module\n  File \"<frozen importlib._bootstrap>\", line 219, in _call_with_frames_removed\n  File \"/code/api/urls.py\", line 3, in <module>\n    from .views import ValidDomainIPView\n  File \"/code/api/views.py\", line 4, in <module>\n    import utility\nModuleNotFoundError: No module named 'utility'", "status_code": 500, "request": "<WSGIRequest: GET '/api/subdomain'>"}
{"message": "Method Not Allowed: /api/subdomain", "status_code": 405, "request": "<WSGIRequest: GET '/api/subdomain'>"}
{"message": "Method Not Allowed: /api/subdomain", "status_code": 405, "request": "<WSGIRequest: GET '/api/subdomain'>"}
{"message": "Bad Request: /api/subdomain", "status_code": 400, "request": "<WSGIRequest: POST '/api/subdomain'>"}
{"message": "Internal Server Error: /", "exc_info": "Traceback (most recent call last):\n  File \"/venv/lib/python3.6/site-packages/django/core/handlers/exception.py\", line 34, in inner\n    response = get_response(request)\n  File \"/venv/lib/python3.6/site-packages/django/core/handlers/base.py\", line 111, in _get_response\n    resolver_match = resolver.resolve(request.path_info)\n  File \"/venv/lib/python3.6/site-packages/django/urls/resolvers.py\", line 491, in resolve\n    for pattern in self.url_patterns:\n  File \"/venv/lib/python3.6/site-packages/django/utils/functional.py\", line 37, in __get__\n    res = instance.__dict__[self.name] = self.func(instance)\n  File \"/venv/lib/python3.6/site-packages/django/urls/resolvers.py\", line 533, in url_patterns\n    patterns = getattr(self.urlconf_module, \"urlpatterns\", self.urlconf_module)\n  File \"/venv/lib/python3.6/site-packages/django/utils/functional.py\", line 37, in __get__\n    res = instance.__dict__[self.name] = self.func(instance)\n  File \"/venv/lib/python3.6/site-packages/django/urls/resolvers.py\", line 526, in urlconf_module\n    return import_module(self.urlconf_name)\n  File \"/usr/local/lib/python3.6/importlib/__init__.py\", line 126, in import_module\n    return _bootstrap._gcd_import(name[level:], package, level)\n  File \"<frozen importlib._bootstrap>\", line 994, in _gcd_import\n  File \"<frozen importlib._bootstrap>\", line 971, in _find_and_load\n  File \"<frozen importlib._bootstrap>\", line 955, in _find_and_load_unlocked\n  File \"<frozen importlib._bootstrap>\", line 665, in _load_unlocked\n  File \"<frozen importlib._bootstrap_external>\", line 678, in exec_module\n  File \"<frozen importlib._bootstrap>\", line 219, in _call_with_frames_removed\n  File \"/code/config/urls.py\", line 24, in <module>\n    url(r'^api/', include('api.urls')),\n  File \"/venv/lib/python3.6/site-packages/django/urls/conf.py\", line 34, in include\n    urlconf_module = import_module(urlconf_module)\n  File \"/usr/local/lib/python3.6/importlib/__init__.py\", line 126, in import_module\n    return _bootstrap._gcd_import(name[level:], package, level)\n  File \"<frozen importlib._bootstrap>\", line 994, in _gcd_import\n  File \"<frozen importlib._bootstrap>\", line 971, in _find_and_load\n  File \"<frozen importlib._bootstrap>\", line 955, in _find_and_load_unlocked\n  File \"<frozen importlib._bootstrap>\", line 665, in _load_unlocked\n  File \"<frozen importlib._bootstrap_external>\", line 678, in exec_module\n  File \"<frozen importlib._bootstrap>\", line 219, in _call_with_frames_removed\n  File \"/code/api/urls.py\", line 3, in <module>\n    from .views import ValidDomainIPView\n  File \"/code/api/views.py\", line 4, in <module>\n    import utility\nModuleNotFoundError: No module named 'utility'", "status_code": 500, "request": "<WSGIRequest: GET '/'>"}
{"message": "Internal Server Error: /favicon.ico", "exc_info": "Traceback (most recent call last):\n  File \"/venv/lib/python3.6/site-packages/django/core/handlers/exception.py\", line 34, in inner\n    response = get_response(request)\n  File \"/venv/lib/python3.6/site-packages/django/utils/deprecation.py\", line 90, in __call__\n    response = self.process_request(request)\n  File \"/venv/lib/python3.6/site-packages/django/middleware/common.py\", line 52, in process_request\n    if self.should_redirect_with_slash(request):\n  File \"/venv/lib/python3.6/site-packages/django/middleware/common.py\", line 70, in should_redirect_with_slash\n    not is_valid_path(request.path_info, urlconf) and\n  File \"/venv/lib/python3.6/site-packages/django/urls/base.py\", line 157, in is_valid_path\n    resolve(path, urlconf)\n  File \"/venv/lib/python3.6/site-packages/django/urls/base.py\", line 24, in resolve\n    return get_resolver(urlconf).resolve(path)\n  File \"/venv/lib/python3.6/site-packages/django/urls/resolvers.py\", line 491, in resolve\n    for pattern in self.url_patterns:\n  File \"/venv/lib/python3.6/site-packages/django/utils/functional.py\", line 37, in __get__\n    res = instance.__dict__[self.name] = self.func(instance)\n  File \"/venv/lib/python3.6/site-packages/django/urls/resolvers.py\", line 533, in url_patterns\n    patterns = getattr(self.urlconf_module, \"urlpatterns\", self.urlconf_module)\n  File \"/venv/lib/python3.6/site-packages/django/utils/functional.py\", line 37, in __get__\n    res = instance.__dict__[self.name] = self.func(instance)\n  File \"/venv/lib/python3.6/site-packages/django/urls/resolvers.py\", line 526, in urlconf_module\n    return import_module(self.urlconf_name)\n  File \"/usr/local/lib/python3.6/importlib/__init__.py\", line 126, in import_module\n    return _bootstrap._gcd_import(name[level:], package, level)\n  File \"<frozen importlib._bootstrap>\", line 994, in _gcd_import\n  File \"<frozen importlib._bootstrap>\", line 971, in _find_and_load\n  File \"<frozen importlib._bootstrap>\", line 955, in _find_and_load_unlocked\n  File \"<frozen importlib._bootstrap>\", line 665, in _load_unlocked\n  File \"<frozen importlib._bootstrap_external>\", line 678, in exec_module\n  File \"<frozen importlib._bootstrap>\", line 219, in _call_with_frames_removed\n  File \"/code/config/urls.py\", line 24, in <module>\n    url(r'^api/', include('api.urls')),\n  File \"/venv/lib/python3.6/site-packages/django/urls/conf.py\", line 34, in include\n    urlconf_module = import_module(urlconf_module)\n  File \"/usr/local/lib/python3.6/importlib/__init__.py\", line 126, in import_module\n    return _bootstrap._gcd_import(name[level:], package, level)\n  File \"<frozen importlib._bootstrap>\", line 994, in _gcd_import\n  File \"<frozen importlib._bootstrap>\", line 971, in _find_and_load\n  File \"<frozen importlib._bootstrap>\", line 955, in _find_and_load_unlocked\n  File \"<frozen importlib._bootstrap>\", line 665, in _load_unlocked\n  File \"<frozen importlib._bootstrap_external>\", line 678, in exec_module\n  File \"<frozen importlib._bootstrap>\", line 219, in _call_with_frames_removed\n  File \"/code/api/urls.py\", line 3, in <module>\n    from .views import ValidDomainIPView\n  File \"/code/api/views.py\", line 4, in <module>\n    import utility\nModuleNotFoundError: No module named 'utility'", "status_code": 500, "request": "<WSGIRequest: GET '/favicon.ico'>"}
{"message": "Internal Server Error: /favicon.ico", "exc_info": "Traceback (most recent call last):\n  File \"/venv/lib/python3.6/site-packages/django/core/handlers/exception.py\", line 34, in inner\n    response = get_response(request)\n  File \"/venv/lib/python3.6/site-packages/django/utils/deprecation.py\", line 90, in __call__\n    response = self.process_request(request)\n  File \"/venv/lib/python3.6/site-packages/django/middleware/common.py\", line 52, in process_request\n    if self.should_redirect_with_slash(request):\n  File \"/venv/lib/python3.6/site-packages/django/middleware/common.py\", line 70, in should_redirect_with_slash\n    not is_valid_path(request.path_info, urlconf) and\n  File \"/venv/lib/python3.6/site-packages/django/urls/base.py\", line 157, in is_valid_path\n    resolve(path, urlconf)\n  File \"/venv/lib/python3.6/site-packages/django/urls/base.py\", line 24, in resolve\n    return get_resolver(urlconf).resolve(path)\n  File \"/venv/lib/python3.6/site-packages/django/urls/resolvers.py\", line 491, in resolve\n    for pattern in self.url_patterns:\n  File \"/venv/lib/python3.6/site-packages/django/utils/functional.py\", line 37, in __get__\n    res = instance.__dict__[self.name] = self.func(instance)\n  File \"/venv/lib/python3.6/site-packages/django/urls/resolvers.py\", line 533, in url_patterns\n    patterns = getattr(self.urlconf_module, \"urlpatterns\", self.urlconf_module)\n  File \"/venv/lib/python3.6/site-packages/django/utils/functional.py\", line 37, in __get__\n    res = instance.__dict__[self.name] = self.func(instance)\n  File \"/venv/lib/python3.6/site-packages/django/urls/resolvers.py\", line 526, in urlconf_module\n    return import_module(self.urlconf_name)\n  File \"/usr/local/lib/python3.6/importlib/__init__.py\", line 126, in import_module\n    return _bootstrap._gcd_import(name[level:], package, level)\n  File \"<frozen importlib._bootstrap>\", line 994, in _gcd_import\n  File \"<frozen importlib._bootstrap>\", line 971, in _find_and_load\n  File \"<frozen importlib._bootstrap>\", line 955, in _find_and_load_unlocked\n  File \"<frozen importlib._bootstrap>\", line 665, in _load_unlocked\n  File \"<frozen importlib._bootstrap_external>\", line 678, in exec_module\n  File \"<frozen importlib._bootstrap>\", line 219, in _call_with_frames_removed\n  File \"/code/config/urls.py\", line 24, in <module>\n    url(r'^api/', include('api.urls')),\n  File \"/venv/lib/python3.6/site-packages/django/urls/conf.py\", line 34, in include\n    urlconf_module = import_module(urlconf_module)\n  File \"/usr/local/lib/python3.6/importlib/__init__.py\", line 126, in import_module\n    return _bootstrap._gcd_import(name[level:], package, level)\n  File \"<frozen importlib._bootstrap>\", line 994, in _gcd_import\n  File \"<frozen importlib._bootstrap>\", line 971, in _find_and_load\n  File \"<frozen importlib._bootstrap>\", line 955, in _find_and_load_unlocked\n  File \"<frozen importlib._bootstrap>\", line 665, in _load_unlocked\n  File \"<frozen importlib._bootstrap_external>\", line 678, in exec_module\n  File \"<frozen importlib._bootstrap>\", line 219, in _call_with_frames_removed\n  File \"/code/api/urls.py\", line 3, in <module>\n    from .views import ValidDomainIPView\n  File \"/code/api/views.py\", line 4, in <module>\n    import utility\nModuleNotFoundError: No module named 'utility'", "status_code": 500, "request": "<WSGIRequest: GET '/favicon.ico'>"}
{"message": "Internal Server Error: /", "exc_info": "Traceback (most recent call last):\n  File \"/venv/lib/python3.6/site-packages/django/core/handlers/exception.py\", line 34, in inner\n    response = get_response(request)\n  File \"/venv/lib/python3.6/site-packages/django/core/handlers/base.py\", line 111, in _get_response\n    resolver_match = resolver.resolve(request.path_info)\n  File \"/venv/lib/python3.6/site-packages/django/urls/resolvers.py\", line 491, in resolve\n    for pattern in self.url_patterns:\n  File \"/venv/lib/python3.6/site-packages/django/utils/functional.py\", line 37, in __get__\n    res = instance.__dict__[self.name] = self.func(instance)\n  File \"/venv/lib/python3.6/site-packages/django/urls/resolvers.py\", line 533, in url_patterns\n    patterns = getattr(self.urlconf_module, \"urlpatterns\", self.urlconf_module)\n  File \"/venv/lib/python3.6/site-packages/django/utils/functional.py\", line 37, in __get__\n    res = instance.__dict__[self.name] = self.func(instance)\n  File \"/venv/lib/python3.6/site-packages/django/urls/resolvers.py\", line 526, in urlconf_module\n    return import_module(self.urlconf_name)\n  File \"/usr/local/lib/python3.6/importlib/__init__.py\", line 126, in import_module\n    return _bootstrap._gcd_import(name[level:], package, level)\n  File \"<frozen importlib._bootstrap>\", line 994, in _gcd_import\n  File \"<frozen importlib._bootstrap>\", line 971, in _find_and_load\n  File \"<frozen importlib._bootstrap>\", line 955, in _find_and_load_unlocked\n  File \"<frozen importlib._bootstrap>\", line 665, in _load_unlocked\n  File \"<frozen importlib._bootstrap_external>\", line 678, in exec_module\n  File \"<frozen importlib._bootstrap>\", line 219, in _call_with_frames_removed\n  File \"/code/config/urls.py\", line 24, in <module>\n    url(r'^api/', include('api.urls')),\n  File \"/venv/lib/python3.6/site-packages/django/urls/conf.py\", line 34, in include\n    urlconf_module = import_module(urlconf_module)\n  File \"/usr/local/lib/python3.6/importlib/__init__.py\", line 126, in import_module\n    return _bootstrap._gcd_import(name[level:], package, level)\n  File \"<frozen importlib._bootstrap>\", line 994, in _gcd_import\n  File \"<frozen importlib._bootstrap>\", line 971, in _find_and_load\n  File \"<frozen importlib._bootstrap>\", line 955, in _find_and_load_unlocked\n  File \"<frozen importlib._bootstrap>\", line 665, in _load_unlocked\n  File \"<frozen importlib._bootstrap_external>\", line 678, in exec_module\n  File \"<frozen importlib._bootstrap>\", line 219, in _call_with_frames_removed\n  File \"/code/api/urls.py\", line 3, in <module>\n    from .views import ValidDomainIPView\n  File \"/code/api/views.py\", line 4, in <module>\n    import api.utility\n  File \"/code/api/utility.py\", line 8\n    def validate_input(self, input):\n                                   ^\nIndentationError: unindent does not match any outer indentation level", "status_code": 500, "request": "<WSGIRequest: GET '/'>"}
{"message": "Internal Server Error: /", "exc_info": "Traceback (most recent call last):\n  File \"/venv/lib/python3.6/site-packages/django/core/handlers/exception.py\", line 34, in inner\n    response = get_response(request)\n  File \"/venv/lib/python3.6/site-packages/django/core/handlers/base.py\", line 111, in _get_response\n    resolver_match = resolver.resolve(request.path_info)\n  File \"/venv/lib/python3.6/site-packages/django/urls/resolvers.py\", line 491, in resolve\n    for pattern in self.url_patterns:\n  File \"/venv/lib/python3.6/site-packages/django/utils/functional.py\", line 37, in __get__\n    res = instance.__dict__[self.name] = self.func(instance)\n  File \"/venv/lib/python3.6/site-packages/django/urls/resolvers.py\", line 533, in url_patterns\n    patterns = getattr(self.urlconf_module, \"urlpatterns\", self.urlconf_module)\n  File \"/venv/lib/python3.6/site-packages/django/utils/functional.py\", line 37, in __get__\n    res = instance.__dict__[self.name] = self.func(instance)\n  File \"/venv/lib/python3.6/site-packages/django/urls/resolvers.py\", line 526, in urlconf_module\n    return import_module(self.urlconf_name)\n  File \"/usr/local/lib/python3.6/importlib/__init__.py\", line 126, in import_module\n    return _bootstrap._gcd_import(name[level:], package, level)\n  File \"<frozen importlib._bootstrap>\", line 994, in _gcd_import\n  File \"<frozen importlib._bootstrap>\", line 971, in _find_and_load\n  File \"<frozen importlib._bootstrap>\", line 955, in _find_and_load_unlocked\n  File \"<frozen importlib._bootstrap>\", line 665, in _load_unlocked\n  File \"<frozen importlib._bootstrap_external>\", line 678, in exec_module\n  File \"<frozen importlib._bootstrap>\", line 219, in _call_with_frames_removed\n  File \"/code/config/urls.py\", line 24, in <module>\n    url(r'^api/', include('api.urls')),\n  File \"/venv/lib/python3.6/site-packages/django/urls/conf.py\", line 34, in include\n    urlconf_module = import_module(urlconf_module)\n  File \"/usr/local/lib/python3.6/importlib/__init__.py\", line 126, in import_module\n    return _bootstrap._gcd_import(name[level:], package, level)\n  File \"<frozen importlib._bootstrap>\", line 994, in _gcd_import\n  File \"<frozen importlib._bootstrap>\", line 971, in _find_and_load\n  File \"<frozen importlib._bootstrap>\", line 955, in _find_and_load_unlocked\n  File \"<frozen importlib._bootstrap>\", line 665, in _load_unlocked\n  File \"<frozen importlib._bootstrap_external>\", line 678, in exec_module\n  File \"<frozen importlib._bootstrap>\", line 219, in _call_with_frames_removed\n  File \"/code/api/urls.py\", line 3, in <module>\n    from .views import ValidDomainIPView\n  File \"/code/api/views.py\", line 4, in <module>\n    import api.utility\n  File \"/code/api/utility.py\", line 8\n    def validate_input(self, input):\n                                   ^\nIndentationError: unindent does not match any outer indentation level", "status_code": 500, "request": "<WSGIRequest: GET '/'>"}
{"message": "Internal Server Error: /", "exc_info": "Traceback (most recent call last):\n  File \"/venv/lib/python3.6/site-packages/django/core/handlers/exception.py\", line 34, in inner\n    response = get_response(request)\n  File \"/venv/lib/python3.6/site-packages/django/core/handlers/base.py\", line 111, in _get_response\n    resolver_match = resolver.resolve(request.path_info)\n  File \"/venv/lib/python3.6/site-packages/django/urls/resolvers.py\", line 491, in resolve\n    for pattern in self.url_patterns:\n  File \"/venv/lib/python3.6/site-packages/django/utils/functional.py\", line 37, in __get__\n    res = instance.__dict__[self.name] = self.func(instance)\n  File \"/venv/lib/python3.6/site-packages/django/urls/resolvers.py\", line 533, in url_patterns\n    patterns = getattr(self.urlconf_module, \"urlpatterns\", self.urlconf_module)\n  File \"/venv/lib/python3.6/site-packages/django/utils/functional.py\", line 37, in __get__\n    res = instance.__dict__[self.name] = self.func(instance)\n  File \"/venv/lib/python3.6/site-packages/django/urls/resolvers.py\", line 526, in urlconf_module\n    return import_module(self.urlconf_name)\n  File \"/usr/local/lib/python3.6/importlib/__init__.py\", line 126, in import_module\n    return _bootstrap._gcd_import(name[level:], package, level)\n  File \"<frozen importlib._bootstrap>\", line 994, in _gcd_import\n  File \"<frozen importlib._bootstrap>\", line 971, in _find_and_load\n  File \"<frozen importlib._bootstrap>\", line 955, in _find_and_load_unlocked\n  File \"<frozen importlib._bootstrap>\", line 665, in _load_unlocked\n  File \"<frozen importlib._bootstrap_external>\", line 678, in exec_module\n  File \"<frozen importlib._bootstrap>\", line 219, in _call_with_frames_removed\n  File \"/code/config/urls.py\", line 24, in <module>\n    url(r'^api/', include('api.urls')),\n  File \"/venv/lib/python3.6/site-packages/django/urls/conf.py\", line 34, in include\n    urlconf_module = import_module(urlconf_module)\n  File \"/usr/local/lib/python3.6/importlib/__init__.py\", line 126, in import_module\n    return _bootstrap._gcd_import(name[level:], package, level)\n  File \"<frozen importlib._bootstrap>\", line 994, in _gcd_import\n  File \"<frozen importlib._bootstrap>\", line 971, in _find_and_load\n  File \"<frozen importlib._bootstrap>\", line 955, in _find_and_load_unlocked\n  File \"<frozen importlib._bootstrap>\", line 665, in _load_unlocked\n  File \"<frozen importlib._bootstrap_external>\", line 678, in exec_module\n  File \"<frozen importlib._bootstrap>\", line 219, in _call_with_frames_removed\n  File \"/code/api/urls.py\", line 3, in <module>\n    from .views import ValidDomainIPView\n  File \"/code/api/views.py\", line 4, in <module>\n    import api.utility\n  File \"/code/api/utility.py\", line 7\n    \"\"\" Decides if input is IP address or domain \"\"\"\n                                                   ^\nIndentationError: expected an indented block", "status_code": 500, "request": "<WSGIRequest: GET '/'>"}
{"message": "Not Found: /", "status_code": 404, "request": "<WSGIRequest: GET '/'>"}
{"message": "Not Found: /", "status_code": 404, "request": "<WSGIRequest: GET '/'>"}
{"message": "Method Not Allowed: /api/", "status_code": 405, "request": "<WSGIRequest: GET '/api/'>"}
{"message": "Internal Server Error: /swagger/", "exc_info": "Traceback (most recent call last):\n  File \"/venv/lib/python3.6/site-packages/django/core/handlers/exception.py\", line 34, in inner\n    response = get_response(request)\n  File \"/venv/lib/python3.6/site-packages/django/core/handlers/base.py\", line 111, in _get_response\n    resolver_match = resolver.resolve(request.path_info)\n  File \"/venv/lib/python3.6/site-packages/django/urls/resolvers.py\", line 491, in resolve\n    for pattern in self.url_patterns:\n  File \"/venv/lib/python3.6/site-packages/django/utils/functional.py\", line 37, in __get__\n    res = instance.__dict__[self.name] = self.func(instance)\n  File \"/venv/lib/python3.6/site-packages/django/urls/resolvers.py\", line 533, in url_patterns\n    patterns = getattr(self.urlconf_module, \"urlpatterns\", self.urlconf_module)\n  File \"/venv/lib/python3.6/site-packages/django/utils/functional.py\", line 37, in __get__\n    res = instance.__dict__[self.name] = self.func(instance)\n  File \"/venv/lib/python3.6/site-packages/django/urls/resolvers.py\", line 526, in urlconf_module\n    return import_module(self.urlconf_name)\n  File \"/usr/local/lib/python3.6/importlib/__init__.py\", line 126, in import_module\n    return _bootstrap._gcd_import(name[level:], package, level)\n  File \"<frozen importlib._bootstrap>\", line 994, in _gcd_import\n  File \"<frozen importlib._bootstrap>\", line 971, in _find_and_load\n  File \"<frozen importlib._bootstrap>\", line 955, in _find_and_load_unlocked\n  File \"<frozen importlib._bootstrap>\", line 665, in _load_unlocked\n  File \"<frozen importlib._bootstrap_external>\", line 678, in exec_module\n  File \"<frozen importlib._bootstrap>\", line 219, in _call_with_frames_removed\n  File \"/code/config/urls.py\", line 24, in <module>\n    url(r'^api/', include('api.urls')),\n  File \"/venv/lib/python3.6/site-packages/django/urls/conf.py\", line 34, in include\n    urlconf_module = import_module(urlconf_module)\n  File \"/usr/local/lib/python3.6/importlib/__init__.py\", line 126, in import_module\n    return _bootstrap._gcd_import(name[level:], package, level)\n  File \"<frozen importlib._bootstrap>\", line 994, in _gcd_import\n  File \"<frozen importlib._bootstrap>\", line 971, in _find_and_load\n  File \"<frozen importlib._bootstrap>\", line 955, in _find_and_load_unlocked\n  File \"<frozen importlib._bootstrap>\", line 665, in _load_unlocked\n  File \"<frozen importlib._bootstrap_external>\", line 678, in exec_module\n  File \"<frozen importlib._bootstrap>\", line 219, in _call_with_frames_removed\n  File \"/code/api/urls.py\", line 3, in <module>\n    from .views import ValidDomainIPView\n  File \"/code/api/views.py\", line 4, in <module>\n    from api.utility import DomainValidation\n  File \"/code/api/utility.py\", line 9\n    def validate_input(self, input):\n                                   ^\nIndentationError: unindent does not match any outer indentation level", "status_code": 500, "request": "<WSGIRequest: GET '/swagger/'>"}
{"message": "Internal Server Error: /swagger/", "exc_info": "Traceback (most recent call last):\n  File \"/venv/lib/python3.6/site-packages/django/core/handlers/exception.py\", line 34, in inner\n    response = get_response(request)\n  File \"/venv/lib/python3.6/site-packages/django/core/handlers/base.py\", line 111, in _get_response\n    resolver_match = resolver.resolve(request.path_info)\n  File \"/venv/lib/python3.6/site-packages/django/urls/resolvers.py\", line 491, in resolve\n    for pattern in self.url_patterns:\n  File \"/venv/lib/python3.6/site-packages/django/utils/functional.py\", line 37, in __get__\n    res = instance.__dict__[self.name] = self.func(instance)\n  File \"/venv/lib/python3.6/site-packages/django/urls/resolvers.py\", line 533, in url_patterns\n    patterns = getattr(self.urlconf_module, \"urlpatterns\", self.urlconf_module)\n  File \"/venv/lib/python3.6/site-packages/django/utils/functional.py\", line 37, in __get__\n    res = instance.__dict__[self.name] = self.func(instance)\n  File \"/venv/lib/python3.6/site-packages/django/urls/resolvers.py\", line 526, in urlconf_module\n    return import_module(self.urlconf_name)\n  File \"/usr/local/lib/python3.6/importlib/__init__.py\", line 126, in import_module\n    return _bootstrap._gcd_import(name[level:], package, level)\n  File \"<frozen importlib._bootstrap>\", line 994, in _gcd_import\n  File \"<frozen importlib._bootstrap>\", line 971, in _find_and_load\n  File \"<frozen importlib._bootstrap>\", line 955, in _find_and_load_unlocked\n  File \"<frozen importlib._bootstrap>\", line 665, in _load_unlocked\n  File \"<frozen importlib._bootstrap_external>\", line 678, in exec_module\n  File \"<frozen importlib._bootstrap>\", line 219, in _call_with_frames_removed\n  File \"/code/config/urls.py\", line 24, in <module>\n    url(r'^api/', include('api.urls')),\n  File \"/venv/lib/python3.6/site-packages/django/urls/conf.py\", line 34, in include\n    urlconf_module = import_module(urlconf_module)\n  File \"/usr/local/lib/python3.6/importlib/__init__.py\", line 126, in import_module\n    return _bootstrap._gcd_import(name[level:], package, level)\n  File \"<frozen importlib._bootstrap>\", line 994, in _gcd_import\n  File \"<frozen importlib._bootstrap>\", line 971, in _find_and_load\n  File \"<frozen importlib._bootstrap>\", line 955, in _find_and_load_unlocked\n  File \"<frozen importlib._bootstrap>\", line 665, in _load_unlocked\n  File \"<frozen importlib._bootstrap_external>\", line 678, in exec_module\n  File \"<frozen importlib._bootstrap>\", line 219, in _call_with_frames_removed\n  File \"/code/api/urls.py\", line 3, in <module>\n    from .views import ValidDomainIPView\n  File \"/code/api/views.py\", line 4, in <module>\n    from api.utility import DomainValidation\n  File \"/code/api/utility.py\", line 9\n    def validate_input(self, input):\n                                   ^\nIndentationError: unindent does not match any outer indentation level", "status_code": 500, "request": "<WSGIRequest: GET '/swagger/'>"}
{"message": "Internal Server Error: /swagger/", "exc_info": "Traceback (most recent call last):\n  File \"/venv/lib/python3.6/site-packages/django/core/handlers/exception.py\", line 34, in inner\n    response = get_response(request)\n  File \"/venv/lib/python3.6/site-packages/django/core/handlers/base.py\", line 111, in _get_response\n    resolver_match = resolver.resolve(request.path_info)\n  File \"/venv/lib/python3.6/site-packages/django/urls/resolvers.py\", line 491, in resolve\n    for pattern in self.url_patterns:\n  File \"/venv/lib/python3.6/site-packages/django/utils/functional.py\", line 37, in __get__\n    res = instance.__dict__[self.name] = self.func(instance)\n  File \"/venv/lib/python3.6/site-packages/django/urls/resolvers.py\", line 533, in url_patterns\n    patterns = getattr(self.urlconf_module, \"urlpatterns\", self.urlconf_module)\n  File \"/venv/lib/python3.6/site-packages/django/utils/functional.py\", line 37, in __get__\n    res = instance.__dict__[self.name] = self.func(instance)\n  File \"/venv/lib/python3.6/site-packages/django/urls/resolvers.py\", line 526, in urlconf_module\n    return import_module(self.urlconf_name)\n  File \"/usr/local/lib/python3.6/importlib/__init__.py\", line 126, in import_module\n    return _bootstrap._gcd_import(name[level:], package, level)\n  File \"<frozen importlib._bootstrap>\", line 994, in _gcd_import\n  File \"<frozen importlib._bootstrap>\", line 971, in _find_and_load\n  File \"<frozen importlib._bootstrap>\", line 955, in _find_and_load_unlocked\n  File \"<frozen importlib._bootstrap>\", line 665, in _load_unlocked\n  File \"<frozen importlib._bootstrap_external>\", line 678, in exec_module\n  File \"<frozen importlib._bootstrap>\", line 219, in _call_with_frames_removed\n  File \"/code/config/urls.py\", line 24, in <module>\n    url(r'^api/', include('api.urls')),\n  File \"/venv/lib/python3.6/site-packages/django/urls/conf.py\", line 34, in include\n    urlconf_module = import_module(urlconf_module)\n  File \"/usr/local/lib/python3.6/importlib/__init__.py\", line 126, in import_module\n    return _bootstrap._gcd_import(name[level:], package, level)\n  File \"<frozen importlib._bootstrap>\", line 994, in _gcd_import\n  File \"<frozen importlib._bootstrap>\", line 971, in _find_and_load\n  File \"<frozen importlib._bootstrap>\", line 955, in _find_and_load_unlocked\n  File \"<frozen importlib._bootstrap>\", line 665, in _load_unlocked\n  File \"<frozen importlib._bootstrap_external>\", line 678, in exec_module\n  File \"<frozen importlib._bootstrap>\", line 219, in _call_with_frames_removed\n  File \"/code/api/urls.py\", line 3, in <module>\n    from .views import ValidDomainIPView\n  File \"/code/api/views.py\", line 4, in <module>\n    from api.utility import DomainValidation\n  File \"/code/api/utility.py\", line 4\n    '''\n    ^\nIndentationError: unexpected indent", "status_code": 500, "request": "<WSGIRequest: GET '/swagger/'>"}
{"message": "Internal Server Error: /swagger/", "exc_info": "Traceback (most recent call last):\n  File \"/venv/lib/python3.6/site-packages/django/core/handlers/exception.py\", line 34, in inner\n    response = get_response(request)\n  File \"/venv/lib/python3.6/site-packages/django/core/handlers/base.py\", line 111, in _get_response\n    resolver_match = resolver.resolve(request.path_info)\n  File \"/venv/lib/python3.6/site-packages/django/urls/resolvers.py\", line 491, in resolve\n    for pattern in self.url_patterns:\n  File \"/venv/lib/python3.6/site-packages/django/utils/functional.py\", line 37, in __get__\n    res = instance.__dict__[self.name] = self.func(instance)\n  File \"/venv/lib/python3.6/site-packages/django/urls/resolvers.py\", line 533, in url_patterns\n    patterns = getattr(self.urlconf_module, \"urlpatterns\", self.urlconf_module)\n  File \"/venv/lib/python3.6/site-packages/django/utils/functional.py\", line 37, in __get__\n    res = instance.__dict__[self.name] = self.func(instance)\n  File \"/venv/lib/python3.6/site-packages/django/urls/resolvers.py\", line 526, in urlconf_module\n    return import_module(self.urlconf_name)\n  File \"/usr/local/lib/python3.6/importlib/__init__.py\", line 126, in import_module\n    return _bootstrap._gcd_import(name[level:], package, level)\n  File \"<frozen importlib._bootstrap>\", line 994, in _gcd_import\n  File \"<frozen importlib._bootstrap>\", line 971, in _find_and_load\n  File \"<frozen importlib._bootstrap>\", line 955, in _find_and_load_unlocked\n  File \"<frozen importlib._bootstrap>\", line 665, in _load_unlocked\n  File \"<frozen importlib._bootstrap_external>\", line 678, in exec_module\n  File \"<frozen importlib._bootstrap>\", line 219, in _call_with_frames_removed\n  File \"/code/config/urls.py\", line 24, in <module>\n    url(r'^api/', include('api.urls')),\n  File \"/venv/lib/python3.6/site-packages/django/urls/conf.py\", line 34, in include\n    urlconf_module = import_module(urlconf_module)\n  File \"/usr/local/lib/python3.6/importlib/__init__.py\", line 126, in import_module\n    return _bootstrap._gcd_import(name[level:], package, level)\n  File \"<frozen importlib._bootstrap>\", line 994, in _gcd_import\n  File \"<frozen importlib._bootstrap>\", line 971, in _find_and_load\n  File \"<frozen importlib._bootstrap>\", line 955, in _find_and_load_unlocked\n  File \"<frozen importlib._bootstrap>\", line 665, in _load_unlocked\n  File \"<frozen importlib._bootstrap_external>\", line 678, in exec_module\n  File \"<frozen importlib._bootstrap>\", line 219, in _call_with_frames_removed\n  File \"/code/api/urls.py\", line 3, in <module>\n    from .views import ValidDomainIPView\n  File \"/code/api/views.py\", line 4, in <module>\n    from api.utility import DomainValidation\n  File \"/code/api/utility.py\", line 22\n    def validate_input(self, input):\n                                   ^\nIndentationError: unindent does not match any outer indentation level", "status_code": 500, "request": "<WSGIRequest: GET '/swagger/'>"}
{"message": "Internal Server Error: /swagger/", "exc_info": "Traceback (most recent call last):\n  File \"/venv/lib/python3.6/site-packages/django/core/handlers/exception.py\", line 34, in inner\n    response = get_response(request)\n  File \"/venv/lib/python3.6/site-packages/django/core/handlers/base.py\", line 111, in _get_response\n    resolver_match = resolver.resolve(request.path_info)\n  File \"/venv/lib/python3.6/site-packages/django/urls/resolvers.py\", line 491, in resolve\n    for pattern in self.url_patterns:\n  File \"/venv/lib/python3.6/site-packages/django/utils/functional.py\", line 37, in __get__\n    res = instance.__dict__[self.name] = self.func(instance)\n  File \"/venv/lib/python3.6/site-packages/django/urls/resolvers.py\", line 533, in url_patterns\n    patterns = getattr(self.urlconf_module, \"urlpatterns\", self.urlconf_module)\n  File \"/venv/lib/python3.6/site-packages/django/utils/functional.py\", line 37, in __get__\n    res = instance.__dict__[self.name] = self.func(instance)\n  File \"/venv/lib/python3.6/site-packages/django/urls/resolvers.py\", line 526, in urlconf_module\n    return import_module(self.urlconf_name)\n  File \"/usr/local/lib/python3.6/importlib/__init__.py\", line 126, in import_module\n    return _bootstrap._gcd_import(name[level:], package, level)\n  File \"<frozen importlib._bootstrap>\", line 994, in _gcd_import\n  File \"<frozen importlib._bootstrap>\", line 971, in _find_and_load\n  File \"<frozen importlib._bootstrap>\", line 955, in _find_and_load_unlocked\n  File \"<frozen importlib._bootstrap>\", line 665, in _load_unlocked\n  File \"<frozen importlib._bootstrap_external>\", line 678, in exec_module\n  File \"<frozen importlib._bootstrap>\", line 219, in _call_with_frames_removed\n  File \"/code/config/urls.py\", line 24, in <module>\n    url(r'^api/', include('api.urls')),\n  File \"/venv/lib/python3.6/site-packages/django/urls/conf.py\", line 34, in include\n    urlconf_module = import_module(urlconf_module)\n  File \"/usr/local/lib/python3.6/importlib/__init__.py\", line 126, in import_module\n    return _bootstrap._gcd_import(name[level:], package, level)\n  File \"<frozen importlib._bootstrap>\", line 994, in _gcd_import\n  File \"<frozen importlib._bootstrap>\", line 971, in _find_and_load\n  File \"<frozen importlib._bootstrap>\", line 955, in _find_and_load_unlocked\n  File \"<frozen importlib._bootstrap>\", line 665, in _load_unlocked\n  File \"<frozen importlib._bootstrap_external>\", line 678, in exec_module\n  File \"<frozen importlib._bootstrap>\", line 219, in _call_with_frames_removed\n  File \"/code/api/urls.py\", line 3, in <module>\n    from .views import ValidDomainIPView\n  File \"/code/api/views.py\", line 4, in <module>\n    from api.utility import DomainValidation\n  File \"/code/api/utility.py\", line 22\n    def validate_input(self, input):\n                                   ^\nIndentationError: unindent does not match any outer indentation level", "status_code": 500, "request": "<WSGIRequest: GET '/swagger/'>"}
{"message": "Internal Server Error: /swagger/", "exc_info": "Traceback (most recent call last):\n  File \"/venv/lib/python3.6/site-packages/django/core/handlers/exception.py\", line 34, in inner\n    response = get_response(request)\n  File \"/venv/lib/python3.6/site-packages/django/core/handlers/base.py\", line 111, in _get_response\n    resolver_match = resolver.resolve(request.path_info)\n  File \"/venv/lib/python3.6/site-packages/django/urls/resolvers.py\", line 491, in resolve\n    for pattern in self.url_patterns:\n  File \"/venv/lib/python3.6/site-packages/django/utils/functional.py\", line 37, in __get__\n    res = instance.__dict__[self.name] = self.func(instance)\n  File \"/venv/lib/python3.6/site-packages/django/urls/resolvers.py\", line 533, in url_patterns\n    patterns = getattr(self.urlconf_module, \"urlpatterns\", self.urlconf_module)\n  File \"/venv/lib/python3.6/site-packages/django/utils/functional.py\", line 37, in __get__\n    res = instance.__dict__[self.name] = self.func(instance)\n  File \"/venv/lib/python3.6/site-packages/django/urls/resolvers.py\", line 526, in urlconf_module\n    return import_module(self.urlconf_name)\n  File \"/usr/local/lib/python3.6/importlib/__init__.py\", line 126, in import_module\n    return _bootstrap._gcd_import(name[level:], package, level)\n  File \"<frozen importlib._bootstrap>\", line 994, in _gcd_import\n  File \"<frozen importlib._bootstrap>\", line 971, in _find_and_load\n  File \"<frozen importlib._bootstrap>\", line 955, in _find_and_load_unlocked\n  File \"<frozen importlib._bootstrap>\", line 665, in _load_unlocked\n  File \"<frozen importlib._bootstrap_external>\", line 678, in exec_module\n  File \"<frozen importlib._bootstrap>\", line 219, in _call_with_frames_removed\n  File \"/code/config/urls.py\", line 24, in <module>\n    url(r'^api/', include('api.urls')),\n  File \"/venv/lib/python3.6/site-packages/django/urls/conf.py\", line 34, in include\n    urlconf_module = import_module(urlconf_module)\n  File \"/usr/local/lib/python3.6/importlib/__init__.py\", line 126, in import_module\n    return _bootstrap._gcd_import(name[level:], package, level)\n  File \"<frozen importlib._bootstrap>\", line 994, in _gcd_import\n  File \"<frozen importlib._bootstrap>\", line 971, in _find_and_load\n  File \"<frozen importlib._bootstrap>\", line 955, in _find_and_load_unlocked\n  File \"<frozen importlib._bootstrap>\", line 665, in _load_unlocked\n  File \"<frozen importlib._bootstrap_external>\", line 678, in exec_module\n  File \"<frozen importlib._bootstrap>\", line 219, in _call_with_frames_removed\n  File \"/code/api/urls.py\", line 3, in <module>\n    from .views import ValidDomainIPView\n  File \"/code/api/views.py\", line 4, in <module>\n    from api.utility import DomainValidation\n  File \"/code/api/utility.py\", line 22\n    def validate_input(self, input):\n                                   ^\nIndentationError: unindent does not match any outer indentation level", "status_code": 500, "request": "<WSGIRequest: GET '/swagger/'>"}
{"message": "Internal Server Error: /swagger/", "exc_info": "Traceback (most recent call last):\n  File \"/venv/lib/python3.6/site-packages/django/core/handlers/exception.py\", line 34, in inner\n    response = get_response(request)\n  File \"/venv/lib/python3.6/site-packages/django/core/handlers/base.py\", line 111, in _get_response\n    resolver_match = resolver.resolve(request.path_info)\n  File \"/venv/lib/python3.6/site-packages/django/urls/resolvers.py\", line 491, in resolve\n    for pattern in self.url_patterns:\n  File \"/venv/lib/python3.6/site-packages/django/utils/functional.py\", line 37, in __get__\n    res = instance.__dict__[self.name] = self.func(instance)\n  File \"/venv/lib/python3.6/site-packages/django/urls/resolvers.py\", line 533, in url_patterns\n    patterns = getattr(self.urlconf_module, \"urlpatterns\", self.urlconf_module)\n  File \"/venv/lib/python3.6/site-packages/django/utils/functional.py\", line 37, in __get__\n    res = instance.__dict__[self.name] = self.func(instance)\n  File \"/venv/lib/python3.6/site-packages/django/urls/resolvers.py\", line 526, in urlconf_module\n    return import_module(self.urlconf_name)\n  File \"/usr/local/lib/python3.6/importlib/__init__.py\", line 126, in import_module\n    return _bootstrap._gcd_import(name[level:], package, level)\n  File \"<frozen importlib._bootstrap>\", line 994, in _gcd_import\n  File \"<frozen importlib._bootstrap>\", line 971, in _find_and_load\n  File \"<frozen importlib._bootstrap>\", line 955, in _find_and_load_unlocked\n  File \"<frozen importlib._bootstrap>\", line 665, in _load_unlocked\n  File \"<frozen importlib._bootstrap_external>\", line 678, in exec_module\n  File \"<frozen importlib._bootstrap>\", line 219, in _call_with_frames_removed\n  File \"/code/config/urls.py\", line 24, in <module>\n    url(r'^api/', include('api.urls')),\n  File \"/venv/lib/python3.6/site-packages/django/urls/conf.py\", line 34, in include\n    urlconf_module = import_module(urlconf_module)\n  File \"/usr/local/lib/python3.6/importlib/__init__.py\", line 126, in import_module\n    return _bootstrap._gcd_import(name[level:], package, level)\n  File \"<frozen importlib._bootstrap>\", line 994, in _gcd_import\n  File \"<frozen importlib._bootstrap>\", line 971, in _find_and_load\n  File \"<frozen importlib._bootstrap>\", line 955, in _find_and_load_unlocked\n  File \"<frozen importlib._bootstrap>\", line 665, in _load_unlocked\n  File \"<frozen importlib._bootstrap_external>\", line 678, in exec_module\n  File \"<frozen importlib._bootstrap>\", line 219, in _call_with_frames_removed\n  File \"/code/api/urls.py\", line 3, in <module>\n    from .views import ValidDomainIPView\n  File \"/code/api/views.py\", line 4, in <module>\n    from api.utility import DomainValidation\n  File \"/code/api/utility.py\", line 21\n    pass\n       ^\nTabError: inconsistent use of tabs and spaces in indentation", "status_code": 500, "request": "<WSGIRequest: GET '/swagger/'>"}
{"message": "Internal Server Error: /swagger/", "exc_info": "Traceback (most recent call last):\n  File \"/venv/lib/python3.6/site-packages/django/core/handlers/exception.py\", line 34, in inner\n    response = get_response(request)\n  File \"/venv/lib/python3.6/site-packages/django/core/handlers/base.py\", line 111, in _get_response\n    resolver_match = resolver.resolve(request.path_info)\n  File \"/venv/lib/python3.6/site-packages/django/urls/resolvers.py\", line 491, in resolve\n    for pattern in self.url_patterns:\n  File \"/venv/lib/python3.6/site-packages/django/utils/functional.py\", line 37, in __get__\n    res = instance.__dict__[self.name] = self.func(instance)\n  File \"/venv/lib/python3.6/site-packages/django/urls/resolvers.py\", line 533, in url_patterns\n    patterns = getattr(self.urlconf_module, \"urlpatterns\", self.urlconf_module)\n  File \"/venv/lib/python3.6/site-packages/django/utils/functional.py\", line 37, in __get__\n    res = instance.__dict__[self.name] = self.func(instance)\n  File \"/venv/lib/python3.6/site-packages/django/urls/resolvers.py\", line 526, in urlconf_module\n    return import_module(self.urlconf_name)\n  File \"/usr/local/lib/python3.6/importlib/__init__.py\", line 126, in import_module\n    return _bootstrap._gcd_import(name[level:], package, level)\n  File \"<frozen importlib._bootstrap>\", line 994, in _gcd_import\n  File \"<frozen importlib._bootstrap>\", line 971, in _find_and_load\n  File \"<frozen importlib._bootstrap>\", line 955, in _find_and_load_unlocked\n  File \"<frozen importlib._bootstrap>\", line 665, in _load_unlocked\n  File \"<frozen importlib._bootstrap_external>\", line 678, in exec_module\n  File \"<frozen importlib._bootstrap>\", line 219, in _call_with_frames_removed\n  File \"/code/config/urls.py\", line 24, in <module>\n    url(r'^api/', include('api.urls')),\n  File \"/venv/lib/python3.6/site-packages/django/urls/conf.py\", line 34, in include\n    urlconf_module = import_module(urlconf_module)\n  File \"/usr/local/lib/python3.6/importlib/__init__.py\", line 126, in import_module\n    return _bootstrap._gcd_import(name[level:], package, level)\n  File \"<frozen importlib._bootstrap>\", line 994, in _gcd_import\n  File \"<frozen importlib._bootstrap>\", line 971, in _find_and_load\n  File \"<frozen importlib._bootstrap>\", line 955, in _find_and_load_unlocked\n  File \"<frozen importlib._bootstrap>\", line 665, in _load_unlocked\n  File \"<frozen importlib._bootstrap_external>\", line 678, in exec_module\n  File \"<frozen importlib._bootstrap>\", line 219, in _call_with_frames_removed\n  File \"/code/api/urls.py\", line 3, in <module>\n    from .views import ValidDomainIPView\n  File \"/code/api/views.py\", line 1, in <module>\n    from api.utils import DomainValidation\n  File \"/code/api/utils.py\", line 18\n    return self.validate_ip_address(input)\n         ^\nIndentationError: expected an indented block", "status_code": 500, "request": "<WSGIRequest: GET '/swagger/'>"}
{"message": "Method Not Allowed: /api/", "status_code": 405, "request": "<WSGIRequest: GET '/api/'>"}
{"message": "Bad Request: /api/", "status_code": 400, "request": "<WSGIRequest: POST '/api/'>"}
{"message": "Bad Request: /api/", "status_code": 400, "request": "<WSGIRequest: POST '/api/'>"}
{"message": "Internal Server Error: /api/", "exc_info": "Traceback (most recent call last):\n  File \"/venv/lib/python3.6/site-packages/django/core/handlers/exception.py\", line 34, in inner\n    response = get_response(request)\n  File \"/venv/lib/python3.6/site-packages/django/core/handlers/base.py\", line 126, in _get_response\n    response = self.process_exception_by_middleware(e, request)\n  File \"/venv/lib/python3.6/site-packages/django/core/handlers/base.py\", line 124, in _get_response\n    response = wrapped_callback(request, *callback_args, **callback_kwargs)\n  File \"/venv/lib/python3.6/site-packages/django/views/decorators/csrf.py\", line 54, in wrapped_view\n    return view_func(*args, **kwargs)\n  File \"/venv/lib/python3.6/site-packages/django/views/generic/base.py\", line 68, in view\n    return self.dispatch(request, *args, **kwargs)\n  File \"/venv/lib/python3.6/site-packages/rest_framework/views.py\", line 483, in dispatch\n    response = self.handle_exception(exc)\n  File \"/venv/lib/python3.6/site-packages/rest_framework/views.py\", line 443, in handle_exception\n    self.raise_uncaught_exception(exc)\n  File \"/venv/lib/python3.6/site-packages/rest_framework/views.py\", line 480, in dispatch\n    response = handler(request, *args, **kwargs)\n  File \"/code/api/views.py\", line 21, in post\n    result = utils.validate_input(\nNameError: name 'utils' is not defined", "status_code": 500, "request": "<WSGIRequest: POST '/api/'>"}
{"message": "Internal Server Error: /api/", "exc_info": "Traceback (most recent call last):\n  File \"/venv/lib/python3.6/site-packages/django/core/handlers/exception.py\", line 34, in inner\n    response = get_response(request)\n  File \"/venv/lib/python3.6/site-packages/django/core/handlers/base.py\", line 111, in _get_response\n    resolver_match = resolver.resolve(request.path_info)\n  File \"/venv/lib/python3.6/site-packages/django/urls/resolvers.py\", line 491, in resolve\n    for pattern in self.url_patterns:\n  File \"/venv/lib/python3.6/site-packages/django/utils/functional.py\", line 37, in __get__\n    res = instance.__dict__[self.name] = self.func(instance)\n  File \"/venv/lib/python3.6/site-packages/django/urls/resolvers.py\", line 533, in url_patterns\n    patterns = getattr(self.urlconf_module, \"urlpatterns\", self.urlconf_module)\n  File \"/venv/lib/python3.6/site-packages/django/utils/functional.py\", line 37, in __get__\n    res = instance.__dict__[self.name] = self.func(instance)\n  File \"/venv/lib/python3.6/site-packages/django/urls/resolvers.py\", line 526, in urlconf_module\n    return import_module(self.urlconf_name)\n  File \"/usr/local/lib/python3.6/importlib/__init__.py\", line 126, in import_module\n    return _bootstrap._gcd_import(name[level:], package, level)\n  File \"<frozen importlib._bootstrap>\", line 994, in _gcd_import\n  File \"<frozen importlib._bootstrap>\", line 971, in _find_and_load\n  File \"<frozen importlib._bootstrap>\", line 955, in _find_and_load_unlocked\n  File \"<frozen importlib._bootstrap>\", line 665, in _load_unlocked\n  File \"<frozen importlib._bootstrap_external>\", line 678, in exec_module\n  File \"<frozen importlib._bootstrap>\", line 219, in _call_with_frames_removed\n  File \"/code/config/urls.py\", line 24, in <module>\n    url(r'^api/', include('api.urls')),\n  File \"/venv/lib/python3.6/site-packages/django/urls/conf.py\", line 34, in include\n    urlconf_module = import_module(urlconf_module)\n  File \"/usr/local/lib/python3.6/importlib/__init__.py\", line 126, in import_module\n    return _bootstrap._gcd_import(name[level:], package, level)\n  File \"<frozen importlib._bootstrap>\", line 994, in _gcd_import\n  File \"<frozen importlib._bootstrap>\", line 971, in _find_and_load\n  File \"<frozen importlib._bootstrap>\", line 955, in _find_and_load_unlocked\n  File \"<frozen importlib._bootstrap>\", line 665, in _load_unlocked\n  File \"<frozen importlib._bootstrap_external>\", line 678, in exec_module\n  File \"<frozen importlib._bootstrap>\", line 219, in _call_with_frames_removed\n  File \"/code/api/urls.py\", line 3, in <module>\n    from .views import ValidDomainIPView\n  File \"/code/api/views.py\", line 7, in <module>\n    class ValidDomainIPView(APIView):\n  File \"/code/api/views.py\", line 17, in ValidDomainIPView\n    utils = api.utils.DomainValidation()\nNameError: name 'api' is not defined", "status_code": 500, "request": "<WSGIRequest: GET '/api/'>"}
{"message": "Internal Server Error: /api/", "exc_info": "Traceback (most recent call last):\n  File \"/venv/lib/python3.6/site-packages/django/core/handlers/exception.py\", line 34, in inner\n    response = get_response(request)\n  File \"/venv/lib/python3.6/site-packages/django/core/handlers/base.py\", line 111, in _get_response\n    resolver_match = resolver.resolve(request.path_info)\n  File \"/venv/lib/python3.6/site-packages/django/urls/resolvers.py\", line 491, in resolve\n    for pattern in self.url_patterns:\n  File \"/venv/lib/python3.6/site-packages/django/utils/functional.py\", line 37, in __get__\n    res = instance.__dict__[self.name] = self.func(instance)\n  File \"/venv/lib/python3.6/site-packages/django/urls/resolvers.py\", line 533, in url_patterns\n    patterns = getattr(self.urlconf_module, \"urlpatterns\", self.urlconf_module)\n  File \"/venv/lib/python3.6/site-packages/django/utils/functional.py\", line 37, in __get__\n    res = instance.__dict__[self.name] = self.func(instance)\n  File \"/venv/lib/python3.6/site-packages/django/urls/resolvers.py\", line 526, in urlconf_module\n    return import_module(self.urlconf_name)\n  File \"/usr/local/lib/python3.6/importlib/__init__.py\", line 126, in import_module\n    return _bootstrap._gcd_import(name[level:], package, level)\n  File \"<frozen importlib._bootstrap>\", line 994, in _gcd_import\n  File \"<frozen importlib._bootstrap>\", line 971, in _find_and_load\n  File \"<frozen importlib._bootstrap>\", line 955, in _find_and_load_unlocked\n  File \"<frozen importlib._bootstrap>\", line 665, in _load_unlocked\n  File \"<frozen importlib._bootstrap_external>\", line 678, in exec_module\n  File \"<frozen importlib._bootstrap>\", line 219, in _call_with_frames_removed\n  File \"/code/config/urls.py\", line 24, in <module>\n    url(r'^api/', include('api.urls')),\n  File \"/venv/lib/python3.6/site-packages/django/urls/conf.py\", line 34, in include\n    urlconf_module = import_module(urlconf_module)\n  File \"/usr/local/lib/python3.6/importlib/__init__.py\", line 126, in import_module\n    return _bootstrap._gcd_import(name[level:], package, level)\n  File \"<frozen importlib._bootstrap>\", line 994, in _gcd_import\n  File \"<frozen importlib._bootstrap>\", line 971, in _find_and_load\n  File \"<frozen importlib._bootstrap>\", line 955, in _find_and_load_unlocked\n  File \"<frozen importlib._bootstrap>\", line 665, in _load_unlocked\n  File \"<frozen importlib._bootstrap_external>\", line 678, in exec_module\n  File \"<frozen importlib._bootstrap>\", line 219, in _call_with_frames_removed\n  File \"/code/api/urls.py\", line 3, in <module>\n    from .views import ValidDomainIPView\n  File \"/code/api/views.py\", line 7, in <module>\n    class ValidDomainIPView(APIView):\n  File \"/code/api/views.py\", line 17, in ValidDomainIPView\n    utils = api.utils.DomainValidation()\nNameError: name 'api' is not defined", "status_code": 500, "request": "<WSGIRequest: GET '/api/'>"}
{"message": "Method Not Allowed: /api/", "status_code": 405, "request": "<WSGIRequest: GET '/api/'>"}
{"message": "Internal Server Error: /api/", "exc_info": "Traceback (most recent call last):\n  File \"/venv/lib/python3.6/site-packages/django/core/handlers/exception.py\", line 34, in inner\n    response = get_response(request)\n  File \"/venv/lib/python3.6/site-packages/django/core/handlers/base.py\", line 126, in _get_response\n    response = self.process_exception_by_middleware(e, request)\n  File \"/venv/lib/python3.6/site-packages/django/core/handlers/base.py\", line 124, in _get_response\n    response = wrapped_callback(request, *callback_args, **callback_kwargs)\n  File \"/venv/lib/python3.6/site-packages/django/views/decorators/csrf.py\", line 54, in wrapped_view\n    return view_func(*args, **kwargs)\n  File \"/venv/lib/python3.6/site-packages/django/views/generic/base.py\", line 68, in view\n    return self.dispatch(request, *args, **kwargs)\n  File \"/venv/lib/python3.6/site-packages/rest_framework/views.py\", line 483, in dispatch\n    response = self.handle_exception(exc)\n  File \"/venv/lib/python3.6/site-packages/rest_framework/views.py\", line 443, in handle_exception\n    self.raise_uncaught_exception(exc)\n  File \"/venv/lib/python3.6/site-packages/rest_framework/views.py\", line 480, in dispatch\n    response = handler(request, *args, **kwargs)\n  File \"/code/api/views.py\", line 21, in post\n    result = domain_validator.validate_input(\nNameError: name 'domain_validator' is not defined", "status_code": 500, "request": "<WSGIRequest: POST '/api/'>"}
{"message": "Method Not Allowed: /api/", "status_code": 405, "request": "<WSGIRequest: GET '/api/'>"}
{"message": "Method Not Allowed: /api/", "status_code": 405, "request": "<WSGIRequest: GET '/api/'>"}
{"message": "Method Not Allowed: /api/", "status_code": 405, "request": "<WSGIRequest: GET '/api/'>"}
{"message": "Internal Server Error: /api/", "exc_info": "Traceback (most recent call last):\n  File \"/venv/lib/python3.6/site-packages/django/core/handlers/exception.py\", line 34, in inner\n    response = get_response(request)\n  File \"/venv/lib/python3.6/site-packages/django/core/handlers/base.py\", line 126, in _get_response\n    response = self.process_exception_by_middleware(e, request)\n  File \"/venv/lib/python3.6/site-packages/django/core/handlers/base.py\", line 124, in _get_response\n    response = wrapped_callback(request, *callback_args, **callback_kwargs)\n  File \"/venv/lib/python3.6/site-packages/django/views/decorators/csrf.py\", line 54, in wrapped_view\n    return view_func(*args, **kwargs)\n  File \"/venv/lib/python3.6/site-packages/django/views/generic/base.py\", line 68, in view\n    return self.dispatch(request, *args, **kwargs)\n  File \"/venv/lib/python3.6/site-packages/rest_framework/views.py\", line 483, in dispatch\n    response = self.handle_exception(exc)\n  File \"/venv/lib/python3.6/site-packages/rest_framework/views.py\", line 443, in handle_exception\n    self.raise_uncaught_exception(exc)\n  File \"/venv/lib/python3.6/site-packages/rest_framework/views.py\", line 480, in dispatch\n    response = handler(request, *args, **kwargs)\n  File \"/code/api/views.py\", line 24, in post\n    input_entered\n  File \"/code/api/utils.py\", line 34, in validate_input\n    if ip_address['ip_address']:\nNameError: name 'ip_address' is not defined", "status_code": 500, "request": "<WSGIRequest: POST '/api/'>"}
{"message": "Method Not Allowed: /api/", "status_code": 405, "request": "<WSGIRequest: GET '/api/'>"}
{"message": "Method Not Allowed: /api/", "status_code": 405, "request": "<WSGIRequest: GET '/api/'>"}
{"message": "Bad Request: /api/", "status_code": 400, "request": "<WSGIRequest: POST '/api/'>"}
{"message": "Method Not Allowed: /api/", "status_code": 405, "request": "<WSGIRequest: GET '/api/'>"}
{"message": "Method Not Allowed: /api/", "status_code": 405, "request": "<WSGIRequest: GET '/api/'>"}
{"message": "Method Not Allowed: /api/", "status_code": 405, "request": "<WSGIRequest: GET '/api/'>"}
{"message": "Method Not Allowed: /api/", "status_code": 405, "request": "<WSGIRequest: GET '/api/'>"}
{"message": "Method Not Allowed: /api/", "status_code": 405, "request": "<WSGIRequest: GET '/api/'>"}
{"message": "Method Not Allowed: /api/", "status_code": 405, "request": "<WSGIRequest: GET '/api/'>"}
{"message": "Method Not Allowed: /api/", "status_code": 405, "request": "<WSGIRequest: GET '/api/'>"}
{"message": "Method Not Allowed: /api/", "status_code": 405, "request": "<WSGIRequest: GET '/api/'>"}
{"message": "Method Not Allowed: /api/", "status_code": 405, "request": "<WSGIRequest: GET '/api/'>"}
{"message": "Bad Request: /api/", "status_code": 400, "request": "<WSGIRequest: POST '/api/'>"}
{"message": "Bad Request: /api/", "status_code": 400, "request": "<WSGIRequest: POST '/api/'>"}
{"message": "Method Not Allowed: /api/", "status_code": 405, "request": "<WSGIRequest: GET '/api/'>"}
{"message": "Bad Request: /api/", "status_code": 400, "request": "<WSGIRequest: POST '/api/'>"}
{"message": "Bad Request: /api/", "status_code": 400, "request": "<WSGIRequest: POST '/api/'>"}
{"message": "Internal Server Error: /api/", "exc_info": "Traceback (most recent call last):\n  File \"/venv/lib/python3.6/site-packages/django/core/handlers/exception.py\", line 34, in inner\n    response = get_response(request)\n  File \"/venv/lib/python3.6/site-packages/django/core/handlers/base.py\", line 111, in _get_response\n    resolver_match = resolver.resolve(request.path_info)\n  File \"/venv/lib/python3.6/site-packages/django/urls/resolvers.py\", line 491, in resolve\n    for pattern in self.url_patterns:\n  File \"/venv/lib/python3.6/site-packages/django/utils/functional.py\", line 37, in __get__\n    res = instance.__dict__[self.name] = self.func(instance)\n  File \"/venv/lib/python3.6/site-packages/django/urls/resolvers.py\", line 533, in url_patterns\n    patterns = getattr(self.urlconf_module, \"urlpatterns\", self.urlconf_module)\n  File \"/venv/lib/python3.6/site-packages/django/utils/functional.py\", line 37, in __get__\n    res = instance.__dict__[self.name] = self.func(instance)\n  File \"/venv/lib/python3.6/site-packages/django/urls/resolvers.py\", line 526, in urlconf_module\n    return import_module(self.urlconf_name)\n  File \"/usr/local/lib/python3.6/importlib/__init__.py\", line 126, in import_module\n    return _bootstrap._gcd_import(name[level:], package, level)\n  File \"<frozen importlib._bootstrap>\", line 994, in _gcd_import\n  File \"<frozen importlib._bootstrap>\", line 971, in _find_and_load\n  File \"<frozen importlib._bootstrap>\", line 955, in _find_and_load_unlocked\n  File \"<frozen importlib._bootstrap>\", line 665, in _load_unlocked\n  File \"<frozen importlib._bootstrap_external>\", line 678, in exec_module\n  File \"<frozen importlib._bootstrap>\", line 219, in _call_with_frames_removed\n  File \"/code/config/urls.py\", line 24, in <module>\n    url(r'^api/', include('api.urls')),\n  File \"/venv/lib/python3.6/site-packages/django/urls/conf.py\", line 34, in include\n    urlconf_module = import_module(urlconf_module)\n  File \"/usr/local/lib/python3.6/importlib/__init__.py\", line 126, in import_module\n    return _bootstrap._gcd_import(name[level:], package, level)\n  File \"<frozen importlib._bootstrap>\", line 994, in _gcd_import\n  File \"<frozen importlib._bootstrap>\", line 971, in _find_and_load\n  File \"<frozen importlib._bootstrap>\", line 955, in _find_and_load_unlocked\n  File \"<frozen importlib._bootstrap>\", line 665, in _load_unlocked\n  File \"<frozen importlib._bootstrap_external>\", line 678, in exec_module\n  File \"<frozen importlib._bootstrap>\", line 219, in _call_with_frames_removed\n  File \"/code/api/urls.py\", line 3, in <module>\n    from .views import ValidDomainIPView\n  File \"/code/api/views.py\", line 1, in <module>\n    from api.utils import DomainValidation\n  File \"/code/api/utils.py\", line 90\n    clean_url = 'https://'+url\n                             ^\nTabError: inconsistent use of tabs and spaces in indentation", "status_code": 500, "request": "<WSGIRequest: POST '/api/'>"}
{"message": "Internal Server Error: /api/", "exc_info": "Traceback (most recent call last):\n  File \"/venv/lib/python3.6/site-packages/django/core/handlers/exception.py\", line 34, in inner\n    response = get_response(request)\n  File \"/venv/lib/python3.6/site-packages/django/core/handlers/base.py\", line 111, in _get_response\n    resolver_match = resolver.resolve(request.path_info)\n  File \"/venv/lib/python3.6/site-packages/django/urls/resolvers.py\", line 491, in resolve\n    for pattern in self.url_patterns:\n  File \"/venv/lib/python3.6/site-packages/django/utils/functional.py\", line 37, in __get__\n    res = instance.__dict__[self.name] = self.func(instance)\n  File \"/venv/lib/python3.6/site-packages/django/urls/resolvers.py\", line 533, in url_patterns\n    patterns = getattr(self.urlconf_module, \"urlpatterns\", self.urlconf_module)\n  File \"/venv/lib/python3.6/site-packages/django/utils/functional.py\", line 37, in __get__\n    res = instance.__dict__[self.name] = self.func(instance)\n  File \"/venv/lib/python3.6/site-packages/django/urls/resolvers.py\", line 526, in urlconf_module\n    return import_module(self.urlconf_name)\n  File \"/usr/local/lib/python3.6/importlib/__init__.py\", line 126, in import_module\n    return _bootstrap._gcd_import(name[level:], package, level)\n  File \"<frozen importlib._bootstrap>\", line 994, in _gcd_import\n  File \"<frozen importlib._bootstrap>\", line 971, in _find_and_load\n  File \"<frozen importlib._bootstrap>\", line 955, in _find_and_load_unlocked\n  File \"<frozen importlib._bootstrap>\", line 665, in _load_unlocked\n  File \"<frozen importlib._bootstrap_external>\", line 678, in exec_module\n  File \"<frozen importlib._bootstrap>\", line 219, in _call_with_frames_removed\n  File \"/code/config/urls.py\", line 24, in <module>\n    url(r'^api/', include('api.urls')),\n  File \"/venv/lib/python3.6/site-packages/django/urls/conf.py\", line 34, in include\n    urlconf_module = import_module(urlconf_module)\n  File \"/usr/local/lib/python3.6/importlib/__init__.py\", line 126, in import_module\n    return _bootstrap._gcd_import(name[level:], package, level)\n  File \"<frozen importlib._bootstrap>\", line 994, in _gcd_import\n  File \"<frozen importlib._bootstrap>\", line 971, in _find_and_load\n  File \"<frozen importlib._bootstrap>\", line 955, in _find_and_load_unlocked\n  File \"<frozen importlib._bootstrap>\", line 665, in _load_unlocked\n  File \"<frozen importlib._bootstrap_external>\", line 678, in exec_module\n  File \"<frozen importlib._bootstrap>\", line 219, in _call_with_frames_removed\n  File \"/code/api/urls.py\", line 3, in <module>\n    from .views import ValidDomainIPView\n  File \"/code/api/views.py\", line 1, in <module>\n    from api.utils import DomainValidation\n  File \"/code/api/utils.py\", line 90\n    clean_url = 'https://'+url\n                             ^\nTabError: inconsistent use of tabs and spaces in indentation", "status_code": 500, "request": "<WSGIRequest: GET '/api/'>"}
{"message": "Method Not Allowed: /api/", "status_code": 405, "request": "<WSGIRequest: GET '/api/'>"}
{"message": "Method Not Allowed: /api/", "status_code": 405, "request": "<WSGIRequest: GET '/api/'>"}
{"message": "Internal Server Error: /api/", "exc_info": "Traceback (most recent call last):\n  File \"/venv/lib/python3.6/site-packages/django/core/handlers/exception.py\", line 34, in inner\n    response = get_response(request)\n  File \"/venv/lib/python3.6/site-packages/django/core/handlers/base.py\", line 126, in _get_response\n    response = self.process_exception_by_middleware(e, request)\n  File \"/venv/lib/python3.6/site-packages/django/core/handlers/base.py\", line 124, in _get_response\n    response = wrapped_callback(request, *callback_args, **callback_kwargs)\n  File \"/venv/lib/python3.6/site-packages/django/views/decorators/csrf.py\", line 54, in wrapped_view\n    return view_func(*args, **kwargs)\n  File \"/venv/lib/python3.6/site-packages/django/views/generic/base.py\", line 68, in view\n    return self.dispatch(request, *args, **kwargs)\n  File \"/venv/lib/python3.6/site-packages/rest_framework/views.py\", line 483, in dispatch\n    response = self.handle_exception(exc)\n  File \"/venv/lib/python3.6/site-packages/rest_framework/views.py\", line 443, in handle_exception\n    self.raise_uncaught_exception(exc)\n  File \"/venv/lib/python3.6/site-packages/rest_framework/views.py\", line 480, in dispatch\n    response = handler(request, *args, **kwargs)\n  File \"/code/api/views.py\", line 26, in post\n    input_entered\n  File \"/code/api/utils.py\", line 63, in validate_input\n    return self.validate_domain(input)\n  File \"/code/api/utils.py\", line 108, in validate_domain\n    reversed_dns = str(resolver.query(clean_domain,\"PTR\")[0])\n  File \"/venv/lib/python3.6/site-packages/dns/resolver.py\", line 1132, in query\n    raise_on_no_answer, source_port)\n  File \"/venv/lib/python3.6/site-packages/dns/resolver.py\", line 1041, in query\n    timeout = self._compute_timeout(start)\n  File \"/venv/lib/python3.6/site-packages/dns/resolver.py\", line 858, in _compute_timeout\n    raise Timeout(timeout=duration)\ndns.exception.Timeout: The DNS operation timed out after 30.00143051147461 seconds", "status_code": 500, "request": "<WSGIRequest: POST '/api/'>"}
{"message": "Internal Server Error: /api/", "exc_info": "Traceback (most recent call last):\n  File \"/venv/lib/python3.6/site-packages/django/core/handlers/exception.py\", line 34, in inner\n    response = get_response(request)\n  File \"/venv/lib/python3.6/site-packages/django/core/handlers/base.py\", line 126, in _get_response\n    response = self.process_exception_by_middleware(e, request)\n  File \"/venv/lib/python3.6/site-packages/django/core/handlers/base.py\", line 124, in _get_response\n    response = wrapped_callback(request, *callback_args, **callback_kwargs)\n  File \"/venv/lib/python3.6/site-packages/django/views/decorators/csrf.py\", line 54, in wrapped_view\n    return view_func(*args, **kwargs)\n  File \"/venv/lib/python3.6/site-packages/django/views/generic/base.py\", line 68, in view\n    return self.dispatch(request, *args, **kwargs)\n  File \"/venv/lib/python3.6/site-packages/rest_framework/views.py\", line 483, in dispatch\n    response = self.handle_exception(exc)\n  File \"/venv/lib/python3.6/site-packages/rest_framework/views.py\", line 443, in handle_exception\n    self.raise_uncaught_exception(exc)\n  File \"/venv/lib/python3.6/site-packages/rest_framework/views.py\", line 480, in dispatch\n    response = handler(request, *args, **kwargs)\n  File \"/code/api/views.py\", line 26, in post\n    input_entered\n  File \"/code/api/utils.py\", line 63, in validate_input\n    return self.validate_domain(input)\n  File \"/code/api/utils.py\", line 108, in validate_domain\n    reversed_dns = str(resolver.query(clean_domain,\"PTR\")[0])\n  File \"/venv/lib/python3.6/site-packages/dns/resolver.py\", line 1132, in query\n    raise_on_no_answer, source_port)\n  File \"/venv/lib/python3.6/site-packages/dns/resolver.py\", line 1041, in query\n    timeout = self._compute_timeout(start)\n  File \"/venv/lib/python3.6/site-packages/dns/resolver.py\", line 858, in _compute_timeout\n    raise Timeout(timeout=duration)\ndns.exception.Timeout: The DNS operation timed out after 30.003029346466064 seconds", "status_code": 500, "request": "<WSGIRequest: POST '/api/'>"}
{"message": "Internal Server Error: /api/", "exc_info": "Traceback (most recent call last):\n  File \"/venv/lib/python3.6/site-packages/django/core/handlers/exception.py\", line 34, in inner\n    response = get_response(request)\n  File \"/venv/lib/python3.6/site-packages/django/core/handlers/base.py\", line 126, in _get_response\n    response = self.process_exception_by_middleware(e, request)\n  File \"/venv/lib/python3.6/site-packages/django/core/handlers/base.py\", line 124, in _get_response\n    response = wrapped_callback(request, *callback_args, **callback_kwargs)\n  File \"/venv/lib/python3.6/site-packages/django/views/decorators/csrf.py\", line 54, in wrapped_view\n    return view_func(*args, **kwargs)\n  File \"/venv/lib/python3.6/site-packages/django/views/generic/base.py\", line 68, in view\n    return self.dispatch(request, *args, **kwargs)\n  File \"/venv/lib/python3.6/site-packages/rest_framework/views.py\", line 483, in dispatch\n    response = self.handle_exception(exc)\n  File \"/venv/lib/python3.6/site-packages/rest_framework/views.py\", line 443, in handle_exception\n    self.raise_uncaught_exception(exc)\n  File \"/venv/lib/python3.6/site-packages/rest_framework/views.py\", line 480, in dispatch\n    response = handler(request, *args, **kwargs)\n  File \"/code/api/views.py\", line 26, in post\n    input_entered\n  File \"/code/api/utils.py\", line 63, in validate_input\n    return self.validate_domain(input)\n  File \"/code/api/utils.py\", line 108, in validate_domain\n    reversed_dns = str(resolver.query(clean_domain,\"PTR\")[0])\n  File \"/venv/lib/python3.6/site-packages/dns/resolver.py\", line 1132, in query\n    raise_on_no_answer, source_port)\n  File \"/venv/lib/python3.6/site-packages/dns/resolver.py\", line 1041, in query\n    timeout = self._compute_timeout(start)\n  File \"/venv/lib/python3.6/site-packages/dns/resolver.py\", line 858, in _compute_timeout\n    raise Timeout(timeout=duration)\ndns.exception.Timeout: The DNS operation timed out after 30.001547813415527 seconds", "status_code": 500, "request": "<WSGIRequest: POST '/api/'>"}
{"message": "Internal Server Error: /api/", "exc_info": "Traceback (most recent call last):\n  File \"/venv/lib/python3.6/site-packages/django/core/handlers/exception.py\", line 34, in inner\n    response = get_response(request)\n  File \"/venv/lib/python3.6/site-packages/django/core/handlers/base.py\", line 126, in _get_response\n    response = self.process_exception_by_middleware(e, request)\n  File \"/venv/lib/python3.6/site-packages/django/core/handlers/base.py\", line 124, in _get_response\n    response = wrapped_callback(request, *callback_args, **callback_kwargs)\n  File \"/venv/lib/python3.6/site-packages/django/views/decorators/csrf.py\", line 54, in wrapped_view\n    return view_func(*args, **kwargs)\n  File \"/venv/lib/python3.6/site-packages/django/views/generic/base.py\", line 68, in view\n    return self.dispatch(request, *args, **kwargs)\n  File \"/venv/lib/python3.6/site-packages/rest_framework/views.py\", line 483, in dispatch\n    response = self.handle_exception(exc)\n  File \"/venv/lib/python3.6/site-packages/rest_framework/views.py\", line 443, in handle_exception\n    self.raise_uncaught_exception(exc)\n  File \"/venv/lib/python3.6/site-packages/rest_framework/views.py\", line 480, in dispatch\n    response = handler(request, *args, **kwargs)\n  File \"/code/api/views.py\", line 26, in post\n    input_entered\n  File \"/code/api/utils.py\", line 63, in validate_input\n    return self.validate_domain(input)\n  File \"/code/api/utils.py\", line 108, in validate_domain\n    reversed_dns = str(resolver.query(clean_domain,\"PTR\")[0])\n  File \"/venv/lib/python3.6/site-packages/dns/resolver.py\", line 1132, in query\n    raise_on_no_answer, source_port)\n  File \"/venv/lib/python3.6/site-packages/dns/resolver.py\", line 1041, in query\n    timeout = self._compute_timeout(start)\n  File \"/venv/lib/python3.6/site-packages/dns/resolver.py\", line 858, in _compute_timeout\n    raise Timeout(timeout=duration)\ndns.exception.Timeout: The DNS operation timed out after 30.00185990333557 seconds", "status_code": 500, "request": "<WSGIRequest: POST '/api/'>"}
{"message": "Internal Server Error: /api/", "exc_info": "Traceback (most recent call last):\n  File \"/venv/lib/python3.6/site-packages/django/core/handlers/exception.py\", line 34, in inner\n    response = get_response(request)\n  File \"/venv/lib/python3.6/site-packages/django/core/handlers/base.py\", line 126, in _get_response\n    response = self.process_exception_by_middleware(e, request)\n  File \"/venv/lib/python3.6/site-packages/django/core/handlers/base.py\", line 124, in _get_response\n    response = wrapped_callback(request, *callback_args, **callback_kwargs)\n  File \"/venv/lib/python3.6/site-packages/django/views/decorators/csrf.py\", line 54, in wrapped_view\n    return view_func(*args, **kwargs)\n  File \"/venv/lib/python3.6/site-packages/django/views/generic/base.py\", line 68, in view\n    return self.dispatch(request, *args, **kwargs)\n  File \"/venv/lib/python3.6/site-packages/rest_framework/views.py\", line 483, in dispatch\n    response = self.handle_exception(exc)\n  File \"/venv/lib/python3.6/site-packages/rest_framework/views.py\", line 443, in handle_exception\n    self.raise_uncaught_exception(exc)\n  File \"/venv/lib/python3.6/site-packages/rest_framework/views.py\", line 480, in dispatch\n    response = handler(request, *args, **kwargs)\n  File \"/code/api/views.py\", line 26, in post\n    input_entered\n  File \"/code/api/utils.py\", line 63, in validate_input\n    return self.validate_domain(input)\n  File \"/code/api/utils.py\", line 108, in validate_domain\n    reversed_dns = str(resolver.query(clean_domain,\"PTR\")[0])\n  File \"/venv/lib/python3.6/site-packages/dns/resolver.py\", line 1132, in query\n    raise_on_no_answer, source_port)\n  File \"/venv/lib/python3.6/site-packages/dns/resolver.py\", line 1041, in query\n    timeout = self._compute_timeout(start)\n  File \"/venv/lib/python3.6/site-packages/dns/resolver.py\", line 858, in _compute_timeout\n    raise Timeout(timeout=duration)\ndns.exception.Timeout: The DNS operation timed out after 30.00172233581543 seconds", "status_code": 500, "request": "<WSGIRequest: POST '/api/'>"}
{"message": "Method Not Allowed: /api/", "status_code": 405, "request": "<WSGIRequest: GET '/api/'>"}
{"message": "Internal Server Error: /api/", "exc_info": "Traceback (most recent call last):\n  File \"/venv/lib/python3.6/site-packages/django/core/handlers/exception.py\", line 34, in inner\n    response = get_response(request)\n  File \"/venv/lib/python3.6/site-packages/django/core/handlers/base.py\", line 126, in _get_response\n    response = self.process_exception_by_middleware(e, request)\n  File \"/venv/lib/python3.6/site-packages/django/core/handlers/base.py\", line 124, in _get_response\n    response = wrapped_callback(request, *callback_args, **callback_kwargs)\n  File \"/venv/lib/python3.6/site-packages/django/views/decorators/csrf.py\", line 54, in wrapped_view\n    return view_func(*args, **kwargs)\n  File \"/venv/lib/python3.6/site-packages/django/views/generic/base.py\", line 68, in view\n    return self.dispatch(request, *args, **kwargs)\n  File \"/venv/lib/python3.6/site-packages/rest_framework/views.py\", line 483, in dispatch\n    response = self.handle_exception(exc)\n  File \"/venv/lib/python3.6/site-packages/rest_framework/views.py\", line 443, in handle_exception\n    self.raise_uncaught_exception(exc)\n  File \"/venv/lib/python3.6/site-packages/rest_framework/views.py\", line 480, in dispatch\n    response = handler(request, *args, **kwargs)\n  File \"/code/api/views.py\", line 26, in post\n    input_entered\n  File \"/code/api/utils.py\", line 63, in validate_input\n    return self.validate_domain(input)\n  File \"/code/api/utils.py\", line 108, in validate_domain\n    reversed_dns = str(resolver.query(clean_domain,\"PTR\")[0])\n  File \"/venv/lib/python3.6/site-packages/dns/resolver.py\", line 1132, in query\n    raise_on_no_answer, source_port)\n  File \"/venv/lib/python3.6/site-packages/dns/resolver.py\", line 1041, in query\n    timeout = self._compute_timeout(start)\n  File \"/venv/lib/python3.6/site-packages/dns/resolver.py\", line 858, in _compute_timeout\n    raise Timeout(timeout=duration)\ndns.exception.Timeout: The DNS operation timed out after 30.00289249420166 seconds", "status_code": 500, "request": "<WSGIRequest: POST '/api/'>"}
{"message": "Internal Server Error: /api/", "exc_info": "Traceback (most recent call last):\n  File \"/venv/lib/python3.6/site-packages/django/core/handlers/exception.py\", line 34, in inner\n    response = get_response(request)\n  File \"/venv/lib/python3.6/site-packages/django/core/handlers/base.py\", line 126, in _get_response\n    response = self.process_exception_by_middleware(e, request)\n  File \"/venv/lib/python3.6/site-packages/django/core/handlers/base.py\", line 124, in _get_response\n    response = wrapped_callback(request, *callback_args, **callback_kwargs)\n  File \"/venv/lib/python3.6/site-packages/django/views/decorators/csrf.py\", line 54, in wrapped_view\n    return view_func(*args, **kwargs)\n  File \"/venv/lib/python3.6/site-packages/django/views/generic/base.py\", line 68, in view\n    return self.dispatch(request, *args, **kwargs)\n  File \"/venv/lib/python3.6/site-packages/rest_framework/views.py\", line 483, in dispatch\n    response = self.handle_exception(exc)\n  File \"/venv/lib/python3.6/site-packages/rest_framework/views.py\", line 443, in handle_exception\n    self.raise_uncaught_exception(exc)\n  File \"/venv/lib/python3.6/site-packages/rest_framework/views.py\", line 480, in dispatch\n    response = handler(request, *args, **kwargs)\n  File \"/code/api/views.py\", line 26, in post\n    input_entered\n  File \"/code/api/utils.py\", line 63, in validate_input\n    return self.validate_domain(input)\n  File \"/code/api/utils.py\", line 108, in validate_domain\n    reversed_dns = str(resolver.query(clean_domain,\"PTR\")[0])\n  File \"/venv/lib/python3.6/site-packages/dns/resolver.py\", line 1132, in query\n    raise_on_no_answer, source_port)\n  File \"/venv/lib/python3.6/site-packages/dns/resolver.py\", line 1041, in query\n    timeout = self._compute_timeout(start)\n  File \"/venv/lib/python3.6/site-packages/dns/resolver.py\", line 858, in _compute_timeout\n    raise Timeout(timeout=duration)\ndns.exception.Timeout: The DNS operation timed out after 30.001383781433105 seconds", "status_code": 500, "request": "<WSGIRequest: POST '/api/'>"}
{"message": "Internal Server Error: /api/", "exc_info": "Traceback (most recent call last):\n  File \"/venv/lib/python3.6/site-packages/django/core/handlers/exception.py\", line 34, in inner\n    response = get_response(request)\n  File \"/venv/lib/python3.6/site-packages/django/core/handlers/base.py\", line 126, in _get_response\n    response = self.process_exception_by_middleware(e, request)\n  File \"/venv/lib/python3.6/site-packages/django/core/handlers/base.py\", line 124, in _get_response\n    response = wrapped_callback(request, *callback_args, **callback_kwargs)\n  File \"/venv/lib/python3.6/site-packages/django/views/decorators/csrf.py\", line 54, in wrapped_view\n    return view_func(*args, **kwargs)\n  File \"/venv/lib/python3.6/site-packages/django/views/generic/base.py\", line 68, in view\n    return self.dispatch(request, *args, **kwargs)\n  File \"/venv/lib/python3.6/site-packages/rest_framework/views.py\", line 483, in dispatch\n    response = self.handle_exception(exc)\n  File \"/venv/lib/python3.6/site-packages/rest_framework/views.py\", line 443, in handle_exception\n    self.raise_uncaught_exception(exc)\n  File \"/venv/lib/python3.6/site-packages/rest_framework/views.py\", line 480, in dispatch\n    response = handler(request, *args, **kwargs)\n  File \"/code/api/views.py\", line 26, in post\n    input_entered\n  File \"/code/api/utils.py\", line 63, in validate_input\n    return self.validate_domain(input)\n  File \"/code/api/utils.py\", line 108, in validate_domain\n    reversed_dns = str(resolver.query(clean_domain,\"PTR\")[0])\n  File \"/venv/lib/python3.6/site-packages/dns/resolver.py\", line 1132, in query\n    raise_on_no_answer, source_port)\n  File \"/venv/lib/python3.6/site-packages/dns/resolver.py\", line 1041, in query\n    timeout = self._compute_timeout(start)\n  File \"/venv/lib/python3.6/site-packages/dns/resolver.py\", line 858, in _compute_timeout\n    raise Timeout(timeout=duration)\ndns.exception.Timeout: The DNS operation timed out after 30.00193738937378 seconds", "status_code": 500, "request": "<WSGIRequest: POST '/api/'>"}
{"message": "Internal Server Error: /api/", "exc_info": "Traceback (most recent call last):\n  File \"/venv/lib/python3.6/site-packages/django/core/handlers/exception.py\", line 34, in inner\n    response = get_response(request)\n  File \"/venv/lib/python3.6/site-packages/django/core/handlers/base.py\", line 126, in _get_response\n    response = self.process_exception_by_middleware(e, request)\n  File \"/venv/lib/python3.6/site-packages/django/core/handlers/base.py\", line 124, in _get_response\n    response = wrapped_callback(request, *callback_args, **callback_kwargs)\n  File \"/venv/lib/python3.6/site-packages/django/views/decorators/csrf.py\", line 54, in wrapped_view\n    return view_func(*args, **kwargs)\n  File \"/venv/lib/python3.6/site-packages/django/views/generic/base.py\", line 68, in view\n    return self.dispatch(request, *args, **kwargs)\n  File \"/venv/lib/python3.6/site-packages/rest_framework/views.py\", line 483, in dispatch\n    response = self.handle_exception(exc)\n  File \"/venv/lib/python3.6/site-packages/rest_framework/views.py\", line 443, in handle_exception\n    self.raise_uncaught_exception(exc)\n  File \"/venv/lib/python3.6/site-packages/rest_framework/views.py\", line 480, in dispatch\n    response = handler(request, *args, **kwargs)\n  File \"/code/api/views.py\", line 26, in post\n    input_entered\n  File \"/code/api/utils.py\", line 63, in validate_input\n    return self.validate_domain(input)\n  File \"/code/api/utils.py\", line 108, in validate_domain\n    reversed_dns = str(resolver.query(clean_domain,\"PTR\")[0])\n  File \"/venv/lib/python3.6/site-packages/dns/resolver.py\", line 1132, in query\n    raise_on_no_answer, source_port)\n  File \"/venv/lib/python3.6/site-packages/dns/resolver.py\", line 1041, in query\n    timeout = self._compute_timeout(start)\n  File \"/venv/lib/python3.6/site-packages/dns/resolver.py\", line 858, in _compute_timeout\n    raise Timeout(timeout=duration)\ndns.exception.Timeout: The DNS operation timed out after 30.00200891494751 seconds", "status_code": 500, "request": "<WSGIRequest: POST '/api/'>"}
{"message": "Internal Server Error: /api/", "exc_info": "Traceback (most recent call last):\n  File \"/venv/lib/python3.6/site-packages/django/core/handlers/exception.py\", line 34, in inner\n    response = get_response(request)\n  File \"/venv/lib/python3.6/site-packages/django/core/handlers/base.py\", line 126, in _get_response\n    response = self.process_exception_by_middleware(e, request)\n  File \"/venv/lib/python3.6/site-packages/django/core/handlers/base.py\", line 124, in _get_response\n    response = wrapped_callback(request, *callback_args, **callback_kwargs)\n  File \"/venv/lib/python3.6/site-packages/django/views/decorators/csrf.py\", line 54, in wrapped_view\n    return view_func(*args, **kwargs)\n  File \"/venv/lib/python3.6/site-packages/django/views/generic/base.py\", line 68, in view\n    return self.dispatch(request, *args, **kwargs)\n  File \"/venv/lib/python3.6/site-packages/rest_framework/views.py\", line 483, in dispatch\n    response = self.handle_exception(exc)\n  File \"/venv/lib/python3.6/site-packages/rest_framework/views.py\", line 443, in handle_exception\n    self.raise_uncaught_exception(exc)\n  File \"/venv/lib/python3.6/site-packages/rest_framework/views.py\", line 480, in dispatch\n    response = handler(request, *args, **kwargs)\n  File \"/code/api/views.py\", line 26, in post\n    input_entered\n  File \"/code/api/utils.py\", line 63, in validate_input\n    return self.validate_domain(input)\n  File \"/code/api/utils.py\", line 108, in validate_domain\n    reversed_dns = str(resolver.query(clean_domain,\"PTR\")[0])\n  File \"/venv/lib/python3.6/site-packages/dns/resolver.py\", line 1132, in query\n    raise_on_no_answer, source_port)\n  File \"/venv/lib/python3.6/site-packages/dns/resolver.py\", line 1041, in query\n    timeout = self._compute_timeout(start)\n  File \"/venv/lib/python3.6/site-packages/dns/resolver.py\", line 858, in _compute_timeout\n    raise Timeout(timeout=duration)\ndns.exception.Timeout: The DNS operation timed out after 30.00114679336548 seconds", "status_code": 500, "request": "<WSGIRequest: POST '/api/'>"}
{"message": "Internal Server Error: /api/", "exc_info": "Traceback (most recent call last):\n  File \"/venv/lib/python3.6/site-packages/django/core/handlers/exception.py\", line 34, in inner\n    response = get_response(request)\n  File \"/venv/lib/python3.6/site-packages/django/core/handlers/base.py\", line 111, in _get_response\n    resolver_match = resolver.resolve(request.path_info)\n  File \"/venv/lib/python3.6/site-packages/django/urls/resolvers.py\", line 491, in resolve\n    for pattern in self.url_patterns:\n  File \"/venv/lib/python3.6/site-packages/django/utils/functional.py\", line 37, in __get__\n    res = instance.__dict__[self.name] = self.func(instance)\n  File \"/venv/lib/python3.6/site-packages/django/urls/resolvers.py\", line 533, in url_patterns\n    patterns = getattr(self.urlconf_module, \"urlpatterns\", self.urlconf_module)\n  File \"/venv/lib/python3.6/site-packages/django/utils/functional.py\", line 37, in __get__\n    res = instance.__dict__[self.name] = self.func(instance)\n  File \"/venv/lib/python3.6/site-packages/django/urls/resolvers.py\", line 526, in urlconf_module\n    return import_module(self.urlconf_name)\n  File \"/usr/local/lib/python3.6/importlib/__init__.py\", line 126, in import_module\n    return _bootstrap._gcd_import(name[level:], package, level)\n  File \"<frozen importlib._bootstrap>\", line 994, in _gcd_import\n  File \"<frozen importlib._bootstrap>\", line 971, in _find_and_load\n  File \"<frozen importlib._bootstrap>\", line 955, in _find_and_load_unlocked\n  File \"<frozen importlib._bootstrap>\", line 665, in _load_unlocked\n  File \"<frozen importlib._bootstrap_external>\", line 678, in exec_module\n  File \"<frozen importlib._bootstrap>\", line 219, in _call_with_frames_removed\n  File \"/code/config/urls.py\", line 24, in <module>\n    url(r'^api/', include('api.urls')),\n  File \"/venv/lib/python3.6/site-packages/django/urls/conf.py\", line 34, in include\n    urlconf_module = import_module(urlconf_module)\n  File \"/usr/local/lib/python3.6/importlib/__init__.py\", line 126, in import_module\n    return _bootstrap._gcd_import(name[level:], package, level)\n  File \"<frozen importlib._bootstrap>\", line 994, in _gcd_import\n  File \"<frozen importlib._bootstrap>\", line 971, in _find_and_load\n  File \"<frozen importlib._bootstrap>\", line 955, in _find_and_load_unlocked\n  File \"<frozen importlib._bootstrap>\", line 665, in _load_unlocked\n  File \"<frozen importlib._bootstrap_external>\", line 678, in exec_module\n  File \"<frozen importlib._bootstrap>\", line 219, in _call_with_frames_removed\n  File \"/code/api/urls.py\", line 3, in <module>\n    from .views import ValidDomainIPView\n  File \"/code/api/views.py\", line 1, in <module>\n    from api.utils import DomainValidation\n  File \"/code/api/utils.py\", line 86\n    def clean_domain(self, unsanatized_url):\n    ^\nIndentationError: unexpected indent", "status_code": 500, "request": "<WSGIRequest: POST '/api/'>"}
{"message": "Internal Server Error: /api/", "exc_info": "Traceback (most recent call last):\n  File \"/venv/lib/python3.6/site-packages/django/core/handlers/exception.py\", line 34, in inner\n    response = get_response(request)\n  File \"/venv/lib/python3.6/site-packages/django/core/handlers/base.py\", line 111, in _get_response\n    resolver_match = resolver.resolve(request.path_info)\n  File \"/venv/lib/python3.6/site-packages/django/urls/resolvers.py\", line 491, in resolve\n    for pattern in self.url_patterns:\n  File \"/venv/lib/python3.6/site-packages/django/utils/functional.py\", line 37, in __get__\n    res = instance.__dict__[self.name] = self.func(instance)\n  File \"/venv/lib/python3.6/site-packages/django/urls/resolvers.py\", line 533, in url_patterns\n    patterns = getattr(self.urlconf_module, \"urlpatterns\", self.urlconf_module)\n  File \"/venv/lib/python3.6/site-packages/django/utils/functional.py\", line 37, in __get__\n    res = instance.__dict__[self.name] = self.func(instance)\n  File \"/venv/lib/python3.6/site-packages/django/urls/resolvers.py\", line 526, in urlconf_module\n    return import_module(self.urlconf_name)\n  File \"/usr/local/lib/python3.6/importlib/__init__.py\", line 126, in import_module\n    return _bootstrap._gcd_import(name[level:], package, level)\n  File \"<frozen importlib._bootstrap>\", line 994, in _gcd_import\n  File \"<frozen importlib._bootstrap>\", line 971, in _find_and_load\n  File \"<frozen importlib._bootstrap>\", line 955, in _find_and_load_unlocked\n  File \"<frozen importlib._bootstrap>\", line 665, in _load_unlocked\n  File \"<frozen importlib._bootstrap_external>\", line 678, in exec_module\n  File \"<frozen importlib._bootstrap>\", line 219, in _call_with_frames_removed\n  File \"/code/config/urls.py\", line 24, in <module>\n    url(r'^api/', include('api.urls')),\n  File \"/venv/lib/python3.6/site-packages/django/urls/conf.py\", line 34, in include\n    urlconf_module = import_module(urlconf_module)\n  File \"/usr/local/lib/python3.6/importlib/__init__.py\", line 126, in import_module\n    return _bootstrap._gcd_import(name[level:], package, level)\n  File \"<frozen importlib._bootstrap>\", line 994, in _gcd_import\n  File \"<frozen importlib._bootstrap>\", line 971, in _find_and_load\n  File \"<frozen importlib._bootstrap>\", line 955, in _find_and_load_unlocked\n  File \"<frozen importlib._bootstrap>\", line 665, in _load_unlocked\n  File \"<frozen importlib._bootstrap_external>\", line 678, in exec_module\n  File \"<frozen importlib._bootstrap>\", line 219, in _call_with_frames_removed\n  File \"/code/api/urls.py\", line 3, in <module>\n    from .views import ValidDomainIPView\n  File \"/code/api/views.py\", line 1, in <module>\n    from api.utils import DomainValidation\n  File \"/code/api/utils.py\", line 86\n    def clean_domain(self, unsanatized_url):\n    ^\nIndentationError: unexpected indent", "status_code": 500, "request": "<WSGIRequest: GET '/api/'>"}
{"message": "Method Not Allowed: /api/", "status_code": 405, "request": "<WSGIRequest: GET '/api/'>"}
{"message": "Internal Server Error: /api/", "exc_info": "Traceback (most recent call last):\n  File \"/venv/lib/python3.6/site-packages/django/core/handlers/exception.py\", line 34, in inner\n    response = get_response(request)\n  File \"/venv/lib/python3.6/site-packages/django/core/handlers/base.py\", line 126, in _get_response\n    response = self.process_exception_by_middleware(e, request)\n  File \"/venv/lib/python3.6/site-packages/django/core/handlers/base.py\", line 124, in _get_response\n    response = wrapped_callback(request, *callback_args, **callback_kwargs)\n  File \"/venv/lib/python3.6/site-packages/django/views/decorators/csrf.py\", line 54, in wrapped_view\n    return view_func(*args, **kwargs)\n  File \"/venv/lib/python3.6/site-packages/django/views/generic/base.py\", line 68, in view\n    return self.dispatch(request, *args, **kwargs)\n  File \"/venv/lib/python3.6/site-packages/rest_framework/views.py\", line 483, in dispatch\n    response = self.handle_exception(exc)\n  File \"/venv/lib/python3.6/site-packages/rest_framework/views.py\", line 443, in handle_exception\n    self.raise_uncaught_exception(exc)\n  File \"/venv/lib/python3.6/site-packages/rest_framework/views.py\", line 480, in dispatch\n    response = handler(request, *args, **kwargs)\n  File \"/code/api/views.py\", line 26, in post\n    input_entered\n  File \"/code/api/utils.py\", line 62, in validate_input\n    return self.validate_domain(input)\n  File \"/code/api/utils.py\", line 114, in validate_domain\n    #reversed_dns = str(resolver.query(clean_domain,\"PTR\")[0])\n  File \"/venv/lib/python3.6/site-packages/dns/resolver.py\", line 1132, in query\n    raise_on_no_answer, source_port)\n  File \"/venv/lib/python3.6/site-packages/dns/resolver.py\", line 1041, in query\n    timeout = self._compute_timeout(start)\n  File \"/venv/lib/python3.6/site-packages/dns/resolver.py\", line 858, in _compute_timeout\n    raise Timeout(timeout=duration)\ndns.exception.Timeout: The DNS operation timed out after 30.00154709815979 seconds", "status_code": 500, "request": "<WSGIRequest: POST '/api/'>"}
{"message": "Internal Server Error: /api/", "exc_info": "Traceback (most recent call last):\n  File \"/venv/lib/python3.6/site-packages/django/core/handlers/exception.py\", line 34, in inner\n    response = get_response(request)\n  File \"/venv/lib/python3.6/site-packages/django/core/handlers/base.py\", line 126, in _get_response\n    response = self.process_exception_by_middleware(e, request)\n  File \"/venv/lib/python3.6/site-packages/django/core/handlers/base.py\", line 124, in _get_response\n    response = wrapped_callback(request, *callback_args, **callback_kwargs)\n  File \"/venv/lib/python3.6/site-packages/django/views/decorators/csrf.py\", line 54, in wrapped_view\n    return view_func(*args, **kwargs)\n  File \"/venv/lib/python3.6/site-packages/django/views/generic/base.py\", line 68, in view\n    return self.dispatch(request, *args, **kwargs)\n  File \"/venv/lib/python3.6/site-packages/rest_framework/views.py\", line 483, in dispatch\n    response = self.handle_exception(exc)\n  File \"/venv/lib/python3.6/site-packages/rest_framework/views.py\", line 443, in handle_exception\n    self.raise_uncaught_exception(exc)\n  File \"/venv/lib/python3.6/site-packages/rest_framework/views.py\", line 480, in dispatch\n    response = handler(request, *args, **kwargs)\n  File \"/code/api/views.py\", line 26, in post\n    input_entered\n  File \"/code/api/utils.py\", line 62, in validate_input\n    return self.validate_domain(input)\n  File \"/code/api/utils.py\", line 114, in validate_domain\n    #reversed_dns = str(resolver.query(clean_domain,\"PTR\")[0])\n  File \"/venv/lib/python3.6/site-packages/dns/resolver.py\", line 1132, in query\n    raise_on_no_answer, source_port)\n  File \"/venv/lib/python3.6/site-packages/dns/resolver.py\", line 1041, in query\n    timeout = self._compute_timeout(start)\n  File \"/venv/lib/python3.6/site-packages/dns/resolver.py\", line 858, in _compute_timeout\n    raise Timeout(timeout=duration)\ndns.exception.Timeout: The DNS operation timed out after 30.002257585525513 seconds", "status_code": 500, "request": "<WSGIRequest: POST '/api/'>"}
{"message": "Internal Server Error: /api/", "exc_info": "Traceback (most recent call last):\n  File \"/venv/lib/python3.6/site-packages/django/core/handlers/exception.py\", line 34, in inner\n    response = get_response(request)\n  File \"/venv/lib/python3.6/site-packages/django/core/handlers/base.py\", line 126, in _get_response\n    response = self.process_exception_by_middleware(e, request)\n  File \"/venv/lib/python3.6/site-packages/django/core/handlers/base.py\", line 124, in _get_response\n    response = wrapped_callback(request, *callback_args, **callback_kwargs)\n  File \"/venv/lib/python3.6/site-packages/django/views/decorators/csrf.py\", line 54, in wrapped_view\n    return view_func(*args, **kwargs)\n  File \"/venv/lib/python3.6/site-packages/django/views/generic/base.py\", line 68, in view\n    return self.dispatch(request, *args, **kwargs)\n  File \"/venv/lib/python3.6/site-packages/rest_framework/views.py\", line 483, in dispatch\n    response = self.handle_exception(exc)\n  File \"/venv/lib/python3.6/site-packages/rest_framework/views.py\", line 443, in handle_exception\n    self.raise_uncaught_exception(exc)\n  File \"/venv/lib/python3.6/site-packages/rest_framework/views.py\", line 480, in dispatch\n    response = handler(request, *args, **kwargs)\n  File \"/code/api/views.py\", line 26, in post\n    input_entered\n  File \"/code/api/utils.py\", line 62, in validate_input\n    return self.validate_domain(input)\n  File \"/code/api/utils.py\", line 114, in validate_domain\n    #reversed_dns = str(resolver.query(clean_domain,\"PTR\")[0])\n  File \"/venv/lib/python3.6/site-packages/dns/resolver.py\", line 1132, in query\n    raise_on_no_answer, source_port)\n  File \"/venv/lib/python3.6/site-packages/dns/resolver.py\", line 1041, in query\n    timeout = self._compute_timeout(start)\n  File \"/venv/lib/python3.6/site-packages/dns/resolver.py\", line 858, in _compute_timeout\n    raise Timeout(timeout=duration)\ndns.exception.Timeout: The DNS operation timed out after 30.001875162124634 seconds", "status_code": 500, "request": "<WSGIRequest: POST '/api/'>"}
{"message": "Internal Server Error: /api/", "exc_info": "Traceback (most recent call last):\n  File \"/venv/lib/python3.6/site-packages/django/core/handlers/exception.py\", line 34, in inner\n    response = get_response(request)\n  File \"/venv/lib/python3.6/site-packages/django/core/handlers/base.py\", line 126, in _get_response\n    response = self.process_exception_by_middleware(e, request)\n  File \"/venv/lib/python3.6/site-packages/django/core/handlers/base.py\", line 124, in _get_response\n    response = wrapped_callback(request, *callback_args, **callback_kwargs)\n  File \"/venv/lib/python3.6/site-packages/django/views/decorators/csrf.py\", line 54, in wrapped_view\n    return view_func(*args, **kwargs)\n  File \"/venv/lib/python3.6/site-packages/django/views/generic/base.py\", line 68, in view\n    return self.dispatch(request, *args, **kwargs)\n  File \"/venv/lib/python3.6/site-packages/rest_framework/views.py\", line 483, in dispatch\n    response = self.handle_exception(exc)\n  File \"/venv/lib/python3.6/site-packages/rest_framework/views.py\", line 443, in handle_exception\n    self.raise_uncaught_exception(exc)\n  File \"/venv/lib/python3.6/site-packages/rest_framework/views.py\", line 480, in dispatch\n    response = handler(request, *args, **kwargs)\n  File \"/code/api/views.py\", line 26, in post\n    input_entered\n  File \"/code/api/utils.py\", line 62, in validate_input\n    return self.validate_domain(input)\n  File \"/code/api/utils.py\", line 114, in validate_domain\n    #reversed_dns = str(resolver.query(clean_domain,\"PTR\")[0])\n  File \"/venv/lib/python3.6/site-packages/dns/resolver.py\", line 1132, in query\n    raise_on_no_answer, source_port)\n  File \"/venv/lib/python3.6/site-packages/dns/resolver.py\", line 1041, in query\n    timeout = self._compute_timeout(start)\n  File \"/venv/lib/python3.6/site-packages/dns/resolver.py\", line 858, in _compute_timeout\n    raise Timeout(timeout=duration)\ndns.exception.Timeout: The DNS operation timed out after 30.003066778182983 seconds", "status_code": 500, "request": "<WSGIRequest: POST '/api/'>"}
{"message": "Internal Server Error: /api/", "exc_info": "Traceback (most recent call last):\n  File \"/venv/lib/python3.6/site-packages/django/core/handlers/exception.py\", line 34, in inner\n    response = get_response(request)\n  File \"/venv/lib/python3.6/site-packages/django/core/handlers/base.py\", line 126, in _get_response\n    response = self.process_exception_by_middleware(e, request)\n  File \"/venv/lib/python3.6/site-packages/django/core/handlers/base.py\", line 124, in _get_response\n    response = wrapped_callback(request, *callback_args, **callback_kwargs)\n  File \"/venv/lib/python3.6/site-packages/django/views/decorators/csrf.py\", line 54, in wrapped_view\n    return view_func(*args, **kwargs)\n  File \"/venv/lib/python3.6/site-packages/django/views/generic/base.py\", line 68, in view\n    return self.dispatch(request, *args, **kwargs)\n  File \"/venv/lib/python3.6/site-packages/rest_framework/views.py\", line 483, in dispatch\n    response = self.handle_exception(exc)\n  File \"/venv/lib/python3.6/site-packages/rest_framework/views.py\", line 443, in handle_exception\n    self.raise_uncaught_exception(exc)\n  File \"/venv/lib/python3.6/site-packages/rest_framework/views.py\", line 480, in dispatch\n    response = handler(request, *args, **kwargs)\n  File \"/code/api/views.py\", line 26, in post\n    input_entered\n  File \"/code/api/utils.py\", line 62, in validate_input\n    return self.validate_domain(input)\n  File \"/code/api/utils.py\", line 114, in validate_domain\n    #reversed_dns = str(resolver.query(clean_domain,\"PTR\")[0])\n  File \"/venv/lib/python3.6/site-packages/dns/resolver.py\", line 1132, in query\n    raise_on_no_answer, source_port)\n  File \"/venv/lib/python3.6/site-packages/dns/resolver.py\", line 1041, in query\n    timeout = self._compute_timeout(start)\n  File \"/venv/lib/python3.6/site-packages/dns/resolver.py\", line 858, in _compute_timeout\n    raise Timeout(timeout=duration)\ndns.exception.Timeout: The DNS operation timed out after 30.002427339553833 seconds", "status_code": 500, "request": "<WSGIRequest: POST '/api/'>"}
{"message": "Internal Server Error: /api/", "exc_info": "Traceback (most recent call last):\n  File \"/venv/lib/python3.6/site-packages/django/core/handlers/exception.py\", line 34, in inner\n    response = get_response(request)\n  File \"/venv/lib/python3.6/site-packages/django/core/handlers/base.py\", line 126, in _get_response\n    response = self.process_exception_by_middleware(e, request)\n  File \"/venv/lib/python3.6/site-packages/django/core/handlers/base.py\", line 124, in _get_response\n    response = wrapped_callback(request, *callback_args, **callback_kwargs)\n  File \"/venv/lib/python3.6/site-packages/django/views/decorators/csrf.py\", line 54, in wrapped_view\n    return view_func(*args, **kwargs)\n  File \"/venv/lib/python3.6/site-packages/django/views/generic/base.py\", line 68, in view\n    return self.dispatch(request, *args, **kwargs)\n  File \"/venv/lib/python3.6/site-packages/rest_framework/views.py\", line 483, in dispatch\n    response = self.handle_exception(exc)\n  File \"/venv/lib/python3.6/site-packages/rest_framework/views.py\", line 443, in handle_exception\n    self.raise_uncaught_exception(exc)\n  File \"/venv/lib/python3.6/site-packages/rest_framework/views.py\", line 480, in dispatch\n    response = handler(request, *args, **kwargs)\n  File \"/code/api/views.py\", line 26, in post\n    input_entered\n  File \"/code/api/utils.py\", line 62, in validate_input\n    return self.validate_domain(input)\n  File \"/code/api/utils.py\", line 114, in validate_domain\n    #reversed_dns = str(resolver.query(clean_domain,\"PTR\")[0])\n  File \"/venv/lib/python3.6/site-packages/dns/resolver.py\", line 1132, in query\n    raise_on_no_answer, source_port)\n  File \"/venv/lib/python3.6/site-packages/dns/resolver.py\", line 1041, in query\n    timeout = self._compute_timeout(start)\n  File \"/venv/lib/python3.6/site-packages/dns/resolver.py\", line 858, in _compute_timeout\n    raise Timeout(timeout=duration)\ndns.exception.Timeout: The DNS operation timed out after 30.00231957435608 seconds", "status_code": 500, "request": "<WSGIRequest: POST '/api/'>"}
{"message": "Internal Server Error: /api/", "exc_info": "Traceback (most recent call last):\n  File \"/venv/lib/python3.6/site-packages/django/core/handlers/exception.py\", line 34, in inner\n    response = get_response(request)\n  File \"/venv/lib/python3.6/site-packages/django/core/handlers/base.py\", line 126, in _get_response\n    response = self.process_exception_by_middleware(e, request)\n  File \"/venv/lib/python3.6/site-packages/django/core/handlers/base.py\", line 124, in _get_response\n    response = wrapped_callback(request, *callback_args, **callback_kwargs)\n  File \"/venv/lib/python3.6/site-packages/django/views/decorators/csrf.py\", line 54, in wrapped_view\n    return view_func(*args, **kwargs)\n  File \"/venv/lib/python3.6/site-packages/django/views/generic/base.py\", line 68, in view\n    return self.dispatch(request, *args, **kwargs)\n  File \"/venv/lib/python3.6/site-packages/rest_framework/views.py\", line 483, in dispatch\n    response = self.handle_exception(exc)\n  File \"/venv/lib/python3.6/site-packages/rest_framework/views.py\", line 443, in handle_exception\n    self.raise_uncaught_exception(exc)\n  File \"/venv/lib/python3.6/site-packages/rest_framework/views.py\", line 480, in dispatch\n    response = handler(request, *args, **kwargs)\n  File \"/code/api/views.py\", line 26, in post\n    input_entered\n  File \"/code/api/utils.py\", line 62, in validate_input\n    return self.validate_domain(input)\n  File \"/code/api/utils.py\", line 114, in validate_domain\n    #reversed_dns = str(resolver.query(clean_domain,\"PTR\")[0])\n  File \"/venv/lib/python3.6/site-packages/dns/resolver.py\", line 1132, in query\n    raise_on_no_answer, source_port)\n  File \"/venv/lib/python3.6/site-packages/dns/resolver.py\", line 1041, in query\n    timeout = self._compute_timeout(start)\n  File \"/venv/lib/python3.6/site-packages/dns/resolver.py\", line 858, in _compute_timeout\n    raise Timeout(timeout=duration)\ndns.exception.Timeout: The DNS operation timed out after 30.002491235733032 seconds", "status_code": 500, "request": "<WSGIRequest: POST '/api/'>"}
{"message": "Internal Server Error: /api/", "exc_info": "Traceback (most recent call last):\n  File \"/venv/lib/python3.6/site-packages/django/core/handlers/exception.py\", line 34, in inner\n    response = get_response(request)\n  File \"/venv/lib/python3.6/site-packages/django/core/handlers/base.py\", line 126, in _get_response\n    response = self.process_exception_by_middleware(e, request)\n  File \"/venv/lib/python3.6/site-packages/django/core/handlers/base.py\", line 124, in _get_response\n    response = wrapped_callback(request, *callback_args, **callback_kwargs)\n  File \"/venv/lib/python3.6/site-packages/django/views/decorators/csrf.py\", line 54, in wrapped_view\n    return view_func(*args, **kwargs)\n  File \"/venv/lib/python3.6/site-packages/django/views/generic/base.py\", line 68, in view\n    return self.dispatch(request, *args, **kwargs)\n  File \"/venv/lib/python3.6/site-packages/rest_framework/views.py\", line 483, in dispatch\n    response = self.handle_exception(exc)\n  File \"/venv/lib/python3.6/site-packages/rest_framework/views.py\", line 443, in handle_exception\n    self.raise_uncaught_exception(exc)\n  File \"/venv/lib/python3.6/site-packages/rest_framework/views.py\", line 480, in dispatch\n    response = handler(request, *args, **kwargs)\n  File \"/code/api/views.py\", line 26, in post\n    input_entered\n  File \"/code/api/utils.py\", line 62, in validate_input\n    return self.validate_domain(input)\n  File \"/code/api/utils.py\", line 114, in validate_domain\n    #reversed_dns = str(resolver.query(clean_domain,\"PTR\")[0])\n  File \"/venv/lib/python3.6/site-packages/dns/resolver.py\", line 1132, in query\n    raise_on_no_answer, source_port)\n  File \"/venv/lib/python3.6/site-packages/dns/resolver.py\", line 1041, in query\n    timeout = self._compute_timeout(start)\n  File \"/venv/lib/python3.6/site-packages/dns/resolver.py\", line 858, in _compute_timeout\n    raise Timeout(timeout=duration)\ndns.exception.Timeout: The DNS operation timed out after 30.002460956573486 seconds", "status_code": 500, "request": "<WSGIRequest: POST '/api/'>"}
{"message": "Internal Server Error: /api/", "exc_info": "Traceback (most recent call last):\n  File \"/venv/lib/python3.6/site-packages/django/core/handlers/exception.py\", line 34, in inner\n    response = get_response(request)\n  File \"/venv/lib/python3.6/site-packages/django/core/handlers/base.py\", line 126, in _get_response\n    response = self.process_exception_by_middleware(e, request)\n  File \"/venv/lib/python3.6/site-packages/django/core/handlers/base.py\", line 124, in _get_response\n    response = wrapped_callback(request, *callback_args, **callback_kwargs)\n  File \"/venv/lib/python3.6/site-packages/django/views/decorators/csrf.py\", line 54, in wrapped_view\n    return view_func(*args, **kwargs)\n  File \"/venv/lib/python3.6/site-packages/django/views/generic/base.py\", line 68, in view\n    return self.dispatch(request, *args, **kwargs)\n  File \"/venv/lib/python3.6/site-packages/rest_framework/views.py\", line 483, in dispatch\n    response = self.handle_exception(exc)\n  File \"/venv/lib/python3.6/site-packages/rest_framework/views.py\", line 443, in handle_exception\n    self.raise_uncaught_exception(exc)\n  File \"/venv/lib/python3.6/site-packages/rest_framework/views.py\", line 480, in dispatch\n    response = handler(request, *args, **kwargs)\n  File \"/code/api/views.py\", line 26, in post\n    input_entered\n  File \"/code/api/utils.py\", line 62, in validate_input\n    return self.validate_domain(input)\n  File \"/code/api/utils.py\", line 114, in validate_domain\n    #reversed_dns = str(resolver.query(clean_domain,\"PTR\")[0])\n  File \"/venv/lib/python3.6/site-packages/dns/resolver.py\", line 1132, in query\n    raise_on_no_answer, source_port)\n  File \"/venv/lib/python3.6/site-packages/dns/resolver.py\", line 1041, in query\n    timeout = self._compute_timeout(start)\n  File \"/venv/lib/python3.6/site-packages/dns/resolver.py\", line 858, in _compute_timeout\n    raise Timeout(timeout=duration)\ndns.exception.Timeout: The DNS operation timed out after 30.002572774887085 seconds", "status_code": 500, "request": "<WSGIRequest: POST '/api/'>"}
{"message": "Method Not Allowed: /api/", "status_code": 405, "request": "<WSGIRequest: GET '/api/'>"}
{"message": "Method Not Allowed: /api/", "status_code": 405, "request": "<WSGIRequest: GET '/api/'>"}
{"message": "Internal Server Error: /api/", "exc_info": "Traceback (most recent call last):\n  File \"/venv/lib/python3.6/site-packages/django/core/handlers/exception.py\", line 34, in inner\n    response = get_response(request)\n  File \"/venv/lib/python3.6/site-packages/django/core/handlers/base.py\", line 126, in _get_response\n    response = self.process_exception_by_middleware(e, request)\n  File \"/venv/lib/python3.6/site-packages/django/core/handlers/base.py\", line 124, in _get_response\n    response = wrapped_callback(request, *callback_args, **callback_kwargs)\n  File \"/venv/lib/python3.6/site-packages/django/views/decorators/csrf.py\", line 54, in wrapped_view\n    return view_func(*args, **kwargs)\n  File \"/venv/lib/python3.6/site-packages/django/views/generic/base.py\", line 68, in view\n    return self.dispatch(request, *args, **kwargs)\n  File \"/venv/lib/python3.6/site-packages/rest_framework/views.py\", line 483, in dispatch\n    response = self.handle_exception(exc)\n  File \"/venv/lib/python3.6/site-packages/rest_framework/views.py\", line 443, in handle_exception\n    self.raise_uncaught_exception(exc)\n  File \"/venv/lib/python3.6/site-packages/rest_framework/views.py\", line 480, in dispatch\n    response = handler(request, *args, **kwargs)\n  File \"/code/api/views.py\", line 26, in post\n    input_entered\n  File \"/code/api/utils.py\", line 62, in validate_input\n    return self.validate_domain(input)\n  File \"/code/api/utils.py\", line 115, in validate_domain\n    print(dns.resolver.query(clean_domain, 'TXT'))\nNameError: name 'dns' is not defined", "status_code": 500, "request": "<WSGIRequest: POST '/api/'>"}
{"message": "Method Not Allowed: /api/", "status_code": 405, "request": "<WSGIRequest: GET '/api/'>"}
{"message": "Method Not Allowed: /api/", "status_code": 405, "request": "<WSGIRequest: GET '/api/'>"}
{"message": "Method Not Allowed: /api/", "status_code": 405, "request": "<WSGIRequest: GET '/api/'>"}
{"message": "Method Not Allowed: /api/", "status_code": 405, "request": "<WSGIRequest: GET '/api/'>"}
{"message": "Internal Server Error: /api/", "exc_info": "Traceback (most recent call last):\n  File \"/venv/lib/python3.6/site-packages/django/core/handlers/exception.py\", line 34, in inner\n    response = get_response(request)\n  File \"/venv/lib/python3.6/site-packages/django/core/handlers/base.py\", line 126, in _get_response\n    response = self.process_exception_by_middleware(e, request)\n  File \"/venv/lib/python3.6/site-packages/django/core/handlers/base.py\", line 124, in _get_response\n    response = wrapped_callback(request, *callback_args, **callback_kwargs)\n  File \"/venv/lib/python3.6/site-packages/django/views/decorators/csrf.py\", line 54, in wrapped_view\n    return view_func(*args, **kwargs)\n  File \"/venv/lib/python3.6/site-packages/django/views/generic/base.py\", line 68, in view\n    return self.dispatch(request, *args, **kwargs)\n  File \"/venv/lib/python3.6/site-packages/rest_framework/views.py\", line 483, in dispatch\n    response = self.handle_exception(exc)\n  File \"/venv/lib/python3.6/site-packages/rest_framework/views.py\", line 443, in handle_exception\n    self.raise_uncaught_exception(exc)\n  File \"/venv/lib/python3.6/site-packages/rest_framework/views.py\", line 480, in dispatch\n    response = handler(request, *args, **kwargs)\n  File \"/code/api/views.py\", line 26, in post\n    input_entered\n  File \"/code/api/utils.py\", line 62, in validate_input\n    else:\n  File \"/code/api/utils.py\", line 115, in validate_domain\n    #reversed_dns = str(resolver.query(clean_domain,\"PTR\")[0])\nNameError: name 'socket' is not defined", "status_code": 500, "request": "<WSGIRequest: POST '/api/'>"}
{"message": "Method Not Allowed: /api/", "status_code": 405, "request": "<WSGIRequest: GET '/api/'>"}
{"message": "Method Not Allowed: /api/", "status_code": 405, "request": "<WSGIRequest: GET '/api/'>"}
{"message": "Method Not Allowed: /api/", "status_code": 405, "request": "<WSGIRequest: GET '/api/'>"}
{"message": "Method Not Allowed: /api/", "status_code": 405, "request": "<WSGIRequest: GET '/api/'>"}
{"message": "Internal Server Error: /api/", "exc_info": "Traceback (most recent call last):\n  File \"/code/api/utils.py\", line 63, in validate_input\n    return self.validate_domain(input)\n  File \"/code/api/utils.py\", line 118, in validate_domain\n    \"reverse_dns\": self.get_reverse_dns(ip_address)\nTypeError: get_reverse_dns() takes 1 positional argument but 2 were given\n\nDuring handling of the above exception, another exception occurred:\n\nTraceback (most recent call last):\n  File \"/venv/lib/python3.6/site-packages/django/core/handlers/exception.py\", line 34, in inner\n    response = get_response(request)\n  File \"/venv/lib/python3.6/site-packages/django/core/handlers/base.py\", line 126, in _get_response\n    response = self.process_exception_by_middleware(e, request)\n  File \"/venv/lib/python3.6/site-packages/django/core/handlers/base.py\", line 124, in _get_response\n    response = wrapped_callback(request, *callback_args, **callback_kwargs)\n  File \"/venv/lib/python3.6/site-packages/django/views/decorators/csrf.py\", line 54, in wrapped_view\n    return view_func(*args, **kwargs)\n  File \"/venv/lib/python3.6/site-packages/django/views/generic/base.py\", line 68, in view\n    return self.dispatch(request, *args, **kwargs)\n  File \"/venv/lib/python3.6/site-packages/rest_framework/views.py\", line 483, in dispatch\n    response = self.handle_exception(exc)\n  File \"/venv/lib/python3.6/site-packages/rest_framework/views.py\", line 443, in handle_exception\n    self.raise_uncaught_exception(exc)\n  File \"/venv/lib/python3.6/site-packages/rest_framework/views.py\", line 480, in dispatch\n    response = handler(request, *args, **kwargs)\n  File \"/code/api/views.py\", line 26, in post\n    input_entered\n  File \"/code/api/utils.py\", line 66, in validate_input\n    return self.validate_domain(input)\n  File \"/code/api/utils.py\", line 118, in validate_domain\n    \"reverse_dns\": self.get_reverse_dns(ip_address)\nTypeError: get_reverse_dns() takes 1 positional argument but 2 were given", "status_code": 500, "request": "<WSGIRequest: POST '/api/'>"}
{"message": "Method Not Allowed: /api/", "status_code": 405, "request": "<WSGIRequest: GET '/api/'>"}
{"message": "Method Not Allowed: /api/", "status_code": 405, "request": "<WSGIRequest: GET '/api/'>"}
{"message": "Method Not Allowed: /api/", "status_code": 405, "request": "<WSGIRequest: GET '/api/'>"}
{"message": "Internal Server Error: /api/", "exc_info": "Traceback (most recent call last):\n  File \"/venv/lib/python3.6/site-packages/django/core/handlers/exception.py\", line 34, in inner\n    response = get_response(request)\n  File \"/venv/lib/python3.6/site-packages/django/core/handlers/base.py\", line 111, in _get_response\n    resolver_match = resolver.resolve(request.path_info)\n  File \"/venv/lib/python3.6/site-packages/django/urls/resolvers.py\", line 491, in resolve\n    for pattern in self.url_patterns:\n  File \"/venv/lib/python3.6/site-packages/django/utils/functional.py\", line 37, in __get__\n    res = instance.__dict__[self.name] = self.func(instance)\n  File \"/venv/lib/python3.6/site-packages/django/urls/resolvers.py\", line 533, in url_patterns\n    patterns = getattr(self.urlconf_module, \"urlpatterns\", self.urlconf_module)\n  File \"/venv/lib/python3.6/site-packages/django/utils/functional.py\", line 37, in __get__\n    res = instance.__dict__[self.name] = self.func(instance)\n  File \"/venv/lib/python3.6/site-packages/django/urls/resolvers.py\", line 526, in urlconf_module\n    return import_module(self.urlconf_name)\n  File \"/usr/local/lib/python3.6/importlib/__init__.py\", line 126, in import_module\n    return _bootstrap._gcd_import(name[level:], package, level)\n  File \"<frozen importlib._bootstrap>\", line 994, in _gcd_import\n  File \"<frozen importlib._bootstrap>\", line 971, in _find_and_load\n  File \"<frozen importlib._bootstrap>\", line 955, in _find_and_load_unlocked\n  File \"<frozen importlib._bootstrap>\", line 665, in _load_unlocked\n  File \"<frozen importlib._bootstrap_external>\", line 678, in exec_module\n  File \"<frozen importlib._bootstrap>\", line 219, in _call_with_frames_removed\n  File \"/code/config/urls.py\", line 24, in <module>\n    url(r'^api/', include('api.urls')),\n  File \"/venv/lib/python3.6/site-packages/django/urls/conf.py\", line 34, in include\n    urlconf_module = import_module(urlconf_module)\n  File \"/usr/local/lib/python3.6/importlib/__init__.py\", line 126, in import_module\n    return _bootstrap._gcd_import(name[level:], package, level)\n  File \"<frozen importlib._bootstrap>\", line 994, in _gcd_import\n  File \"<frozen importlib._bootstrap>\", line 971, in _find_and_load\n  File \"<frozen importlib._bootstrap>\", line 955, in _find_and_load_unlocked\n  File \"<frozen importlib._bootstrap>\", line 665, in _load_unlocked\n  File \"<frozen importlib._bootstrap_external>\", line 678, in exec_module\n  File \"<frozen importlib._bootstrap>\", line 219, in _call_with_frames_removed\n  File \"/code/api/urls.py\", line 7, in <module>\n    url('^subdomain', SubdomainView.as_view(), name='get_list_of_subdomains'),\nNameError: name 'SubdomainView' is not defined", "status_code": 500, "request": "<WSGIRequest: GET '/api/'>"}
{"message": "Method Not Allowed: /api/", "status_code": 405, "request": "<WSGIRequest: GET '/api/'>"}
{"message": "Internal Server Error: /api/", "exc_info": "Traceback (most recent call last):\n  File \"/venv/lib/python3.6/site-packages/django/core/handlers/exception.py\", line 34, in inner\n    response = get_response(request)\n  File \"/venv/lib/python3.6/site-packages/django/core/handlers/base.py\", line 126, in _get_response\n    response = self.process_exception_by_middleware(e, request)\n  File \"/venv/lib/python3.6/site-packages/django/core/handlers/base.py\", line 124, in _get_response\n    response = wrapped_callback(request, *callback_args, **callback_kwargs)\n  File \"/venv/lib/python3.6/site-packages/django/views/decorators/csrf.py\", line 54, in wrapped_view\n    return view_func(*args, **kwargs)\n  File \"/venv/lib/python3.6/site-packages/django/views/generic/base.py\", line 68, in view\n    return self.dispatch(request, *args, **kwargs)\n  File \"/venv/lib/python3.6/site-packages/rest_framework/views.py\", line 483, in dispatch\n    response = self.handle_exception(exc)\n  File \"/venv/lib/python3.6/site-packages/rest_framework/views.py\", line 443, in handle_exception\n    self.raise_uncaught_exception(exc)\n  File \"/venv/lib/python3.6/site-packages/rest_framework/views.py\", line 480, in dispatch\n    response = handler(request, *args, **kwargs)\n  File \"/code/api/views.py\", line 24, in post\n    input_entered\n  File \"/code/api/utils.py\", line 63, in validate_input\n    return self.validate_domain(input)\n  File \"/code/api/utils.py\", line 120, in validate_domain\n    \"reverse_dns\": self.get_reverse_dns(ip_address)\n  File \"/code/api/utils.py\", line 126, in get_reverse_dns\n    return socket.gethostbyaddr(ip_address)[0]\n  File \"/venv/lib/python3.6/site-packages/gevent/_socketcommon.py\", line 222, in gethostbyaddr\n    return get_hub().resolver.gethostbyaddr(ip_address)\n  File \"/venv/lib/python3.6/site-packages/gevent/resolver/thread.py\", line 68, in gethostbyaddr\n    return self.pool.apply(_socket.gethostbyaddr, args, kwargs)\n  File \"/venv/lib/python3.6/site-packages/gevent/pool.py\", line 159, in apply\n    return self.spawn(func, *args, **kwds).get()\n  File \"src/gevent/event.py\", line 381, in gevent._event.AsyncResult.get\n  File \"src/gevent/event.py\", line 409, in gevent._event.AsyncResult.get\n  File \"src/gevent/event.py\", line 399, in gevent._event.AsyncResult.get\n  File \"src/gevent/event.py\", line 379, in gevent._event.AsyncResult._raise_exception\n  File \"/venv/lib/python3.6/site-packages/gevent/_compat.py\", line 47, in reraise\n    raise value.with_traceback(tb)\n  File \"/venv/lib/python3.6/site-packages/gevent/threadpool.py\", line 281, in _worker\n    value = func(*args, **kwargs)\nsocket.herror: [Errno 1] Unknown host", "status_code": 500, "request": "<WSGIRequest: POST '/api/'>"}
{"message": "Method Not Allowed: /api/", "status_code": 405, "request": "<WSGIRequest: GET '/api/'>"}
{"message": "Internal Server Error: /api/", "exc_info": "Traceback (most recent call last):\n  File \"/venv/lib/python3.6/site-packages/django/core/handlers/exception.py\", line 34, in inner\n    response = get_response(request)\n  File \"/venv/lib/python3.6/site-packages/django/core/handlers/base.py\", line 126, in _get_response\n    response = self.process_exception_by_middleware(e, request)\n  File \"/venv/lib/python3.6/site-packages/django/core/handlers/base.py\", line 124, in _get_response\n    response = wrapped_callback(request, *callback_args, **callback_kwargs)\n  File \"/venv/lib/python3.6/site-packages/django/views/decorators/csrf.py\", line 54, in wrapped_view\n    return view_func(*args, **kwargs)\n  File \"/venv/lib/python3.6/site-packages/django/views/generic/base.py\", line 68, in view\n    return self.dispatch(request, *args, **kwargs)\n  File \"/venv/lib/python3.6/site-packages/rest_framework/views.py\", line 483, in dispatch\n    response = self.handle_exception(exc)\n  File \"/venv/lib/python3.6/site-packages/rest_framework/views.py\", line 443, in handle_exception\n    self.raise_uncaught_exception(exc)\n  File \"/venv/lib/python3.6/site-packages/rest_framework/views.py\", line 480, in dispatch\n    response = handler(request, *args, **kwargs)\n  File \"/code/api/views.py\", line 24, in post\n    input_entered\n  File \"/code/api/utils.py\", line 63, in validate_input\n    return self.validate_domain(input)\n  File \"/code/api/utils.py\", line 120, in validate_domain\n    \"reverse_dns\": self.get_reverse_dns(ip_address)\n  File \"/code/api/utils.py\", line 126, in get_reverse_dns\n    return socket.gethostbyaddr(ip_address)[0]\n  File \"/venv/lib/python3.6/site-packages/gevent/_socketcommon.py\", line 222, in gethostbyaddr\n    return get_hub().resolver.gethostbyaddr(ip_address)\n  File \"/venv/lib/python3.6/site-packages/gevent/resolver/thread.py\", line 68, in gethostbyaddr\n    return self.pool.apply(_socket.gethostbyaddr, args, kwargs)\n  File \"/venv/lib/python3.6/site-packages/gevent/pool.py\", line 159, in apply\n    return self.spawn(func, *args, **kwds).get()\n  File \"src/gevent/event.py\", line 381, in gevent._event.AsyncResult.get\n  File \"src/gevent/event.py\", line 409, in gevent._event.AsyncResult.get\n  File \"src/gevent/event.py\", line 399, in gevent._event.AsyncResult.get\n  File \"src/gevent/event.py\", line 379, in gevent._event.AsyncResult._raise_exception\n  File \"/venv/lib/python3.6/site-packages/gevent/_compat.py\", line 47, in reraise\n    raise value.with_traceback(tb)\n  File \"/venv/lib/python3.6/site-packages/gevent/threadpool.py\", line 281, in _worker\n    value = func(*args, **kwargs)\nsocket.herror: [Errno 1] Unknown host", "status_code": 500, "request": "<WSGIRequest: POST '/api/'>"}
{"message": "Method Not Allowed: /api/", "status_code": 405, "request": "<WSGIRequest: GET '/api/'>"}
{"message": "Internal Server Error: /api/", "exc_info": "Traceback (most recent call last):\n  File \"/venv/lib/python3.6/site-packages/django/core/handlers/exception.py\", line 34, in inner\n    response = get_response(request)\n  File \"/venv/lib/python3.6/site-packages/django/core/handlers/base.py\", line 126, in _get_response\n    response = self.process_exception_by_middleware(e, request)\n  File \"/venv/lib/python3.6/site-packages/django/core/handlers/base.py\", line 124, in _get_response\n    response = wrapped_callback(request, *callback_args, **callback_kwargs)\n  File \"/venv/lib/python3.6/site-packages/django/views/decorators/csrf.py\", line 54, in wrapped_view\n    return view_func(*args, **kwargs)\n  File \"/venv/lib/python3.6/site-packages/django/views/generic/base.py\", line 68, in view\n    return self.dispatch(request, *args, **kwargs)\n  File \"/venv/lib/python3.6/site-packages/rest_framework/views.py\", line 483, in dispatch\n    response = self.handle_exception(exc)\n  File \"/venv/lib/python3.6/site-packages/rest_framework/views.py\", line 443, in handle_exception\n    self.raise_uncaught_exception(exc)\n  File \"/venv/lib/python3.6/site-packages/rest_framework/views.py\", line 480, in dispatch\n    response = handler(request, *args, **kwargs)\n  File \"/code/api/views.py\", line 24, in post\n    input_entered\n  File \"/code/api/utils.py\", line 54, in validate_input\n    json_contains_ip_address = self.validate_ip_address(input)\n  File \"/code/api/utils.py\", line 78, in validate_ip_address\n    return {'domain':self.get_reverse_dns(ip_address),\n  File \"/code/api/utils.py\", line 126, in get_reverse_dns\n    return socket.gethostbyaddr(ip_address)[0]\n  File \"/venv/lib/python3.6/site-packages/gevent/_socketcommon.py\", line 222, in gethostbyaddr\n    return get_hub().resolver.gethostbyaddr(ip_address)\n  File \"/venv/lib/python3.6/site-packages/gevent/resolver/thread.py\", line 68, in gethostbyaddr\n    return self.pool.apply(_socket.gethostbyaddr, args, kwargs)\n  File \"/venv/lib/python3.6/site-packages/gevent/pool.py\", line 159, in apply\n    return self.spawn(func, *args, **kwds).get()\n  File \"src/gevent/event.py\", line 381, in gevent._event.AsyncResult.get\n  File \"src/gevent/event.py\", line 409, in gevent._event.AsyncResult.get\n  File \"src/gevent/event.py\", line 399, in gevent._event.AsyncResult.get\n  File \"src/gevent/event.py\", line 379, in gevent._event.AsyncResult._raise_exception\n  File \"/venv/lib/python3.6/site-packages/gevent/_compat.py\", line 47, in reraise\n    raise value.with_traceback(tb)\n  File \"/venv/lib/python3.6/site-packages/gevent/threadpool.py\", line 281, in _worker\n    value = func(*args, **kwargs)\nsocket.herror: [Errno 1] Unknown host", "status_code": 500, "request": "<WSGIRequest: POST '/api/'>"}
{"message": "Method Not Allowed: /api/", "status_code": 405, "request": "<WSGIRequest: GET '/api/'>"}
{"message": "Internal Server Error: /api/", "exc_info": "Traceback (most recent call last):\n  File \"/code/api/utils.py\", line 129, in get_reverse_dns\n    reverse_dns = socket.gethostbyaddr(ip_address)[0]\n  File \"/venv/lib/python3.6/site-packages/gevent/_socketcommon.py\", line 222, in gethostbyaddr\n    return get_hub().resolver.gethostbyaddr(ip_address)\n  File \"/venv/lib/python3.6/site-packages/gevent/resolver/thread.py\", line 68, in gethostbyaddr\n    return self.pool.apply(_socket.gethostbyaddr, args, kwargs)\n  File \"/venv/lib/python3.6/site-packages/gevent/pool.py\", line 159, in apply\n    return self.spawn(func, *args, **kwds).get()\n  File \"src/gevent/event.py\", line 381, in gevent._event.AsyncResult.get\n  File \"src/gevent/event.py\", line 409, in gevent._event.AsyncResult.get\n  File \"src/gevent/event.py\", line 399, in gevent._event.AsyncResult.get\n  File \"src/gevent/event.py\", line 379, in gevent._event.AsyncResult._raise_exception\n  File \"/venv/lib/python3.6/site-packages/gevent/_compat.py\", line 47, in reraise\n    raise value.with_traceback(tb)\n  File \"/venv/lib/python3.6/site-packages/gevent/threadpool.py\", line 281, in _worker\n    value = func(*args, **kwargs)\nsocket.herror: [Errno 1] Unknown host\n\nDuring handling of the above exception, another exception occurred:\n\nTraceback (most recent call last):\n  File \"/venv/lib/python3.6/site-packages/django/core/handlers/exception.py\", line 34, in inner\n    response = get_response(request)\n  File \"/venv/lib/python3.6/site-packages/django/core/handlers/base.py\", line 126, in _get_response\n    response = self.process_exception_by_middleware(e, request)\n  File \"/venv/lib/python3.6/site-packages/django/core/handlers/base.py\", line 124, in _get_response\n    response = wrapped_callback(request, *callback_args, **callback_kwargs)\n  File \"/venv/lib/python3.6/site-packages/django/views/decorators/csrf.py\", line 54, in wrapped_view\n    return view_func(*args, **kwargs)\n  File \"/venv/lib/python3.6/site-packages/django/views/generic/base.py\", line 68, in view\n    return self.dispatch(request, *args, **kwargs)\n  File \"/venv/lib/python3.6/site-packages/rest_framework/views.py\", line 483, in dispatch\n    response = self.handle_exception(exc)\n  File \"/venv/lib/python3.6/site-packages/rest_framework/views.py\", line 443, in handle_exception\n    self.raise_uncaught_exception(exc)\n  File \"/venv/lib/python3.6/site-packages/rest_framework/views.py\", line 480, in dispatch\n    response = handler(request, *args, **kwargs)\n  File \"/code/api/views.py\", line 24, in post\n    input_entered\n  File \"/code/api/utils.py\", line 63, in validate_input\n    return self.validate_domain(input)\n  File \"/code/api/utils.py\", line 120, in validate_domain\n    \"reverse_dns\": self.get_reverse_dns(ip_address)\n  File \"/code/api/utils.py\", line 132, in get_reverse_dns\n    reverse_dns = socket.gethostbyaddr(ip_address)[0]\n  File \"/venv/lib/python3.6/site-packages/gevent/_socketcommon.py\", line 222, in gethostbyaddr\n    return get_hub().resolver.gethostbyaddr(ip_address)\n  File \"/venv/lib/python3.6/site-packages/gevent/resolver/thread.py\", line 68, in gethostbyaddr\n    return self.pool.apply(_socket.gethostbyaddr, args, kwargs)\n  File \"/venv/lib/python3.6/site-packages/gevent/pool.py\", line 159, in apply\n    return self.spawn(func, *args, **kwds).get()\n  File \"src/gevent/event.py\", line 381, in gevent._event.AsyncResult.get\n  File \"src/gevent/event.py\", line 409, in gevent._event.AsyncResult.get\n  File \"src/gevent/event.py\", line 399, in gevent._event.AsyncResult.get\n  File \"src/gevent/event.py\", line 379, in gevent._event.AsyncResult._raise_exception\n  File \"/venv/lib/python3.6/site-packages/gevent/_compat.py\", line 47, in reraise\n    raise value.with_traceback(tb)\n  File \"/venv/lib/python3.6/site-packages/gevent/threadpool.py\", line 281, in _worker\n    value = func(*args, **kwargs)\nsocket.gaierror: [Errno -2] Name or service not known", "status_code": 500, "request": "<WSGIRequest: POST '/api/'>"}
{"message": "Method Not Allowed: /api/", "status_code": 405, "request": "<WSGIRequest: GET '/api/'>"}
{"message": "Internal Server Error: /api/", "exc_info": "Traceback (most recent call last):\n  File \"/code/api/utils.py\", line 129, in get_reverse_dns\n    reverse_dns = socket.gethostbyaddr(ip_address)[0]\n  File \"/venv/lib/python3.6/site-packages/gevent/_socketcommon.py\", line 222, in gethostbyaddr\n    return get_hub().resolver.gethostbyaddr(ip_address)\n  File \"/venv/lib/python3.6/site-packages/gevent/resolver/thread.py\", line 68, in gethostbyaddr\n    return self.pool.apply(_socket.gethostbyaddr, args, kwargs)\n  File \"/venv/lib/python3.6/site-packages/gevent/pool.py\", line 159, in apply\n    return self.spawn(func, *args, **kwds).get()\n  File \"src/gevent/event.py\", line 381, in gevent._event.AsyncResult.get\n  File \"src/gevent/event.py\", line 409, in gevent._event.AsyncResult.get\n  File \"src/gevent/event.py\", line 399, in gevent._event.AsyncResult.get\n  File \"src/gevent/event.py\", line 379, in gevent._event.AsyncResult._raise_exception\n  File \"/venv/lib/python3.6/site-packages/gevent/_compat.py\", line 47, in reraise\n    raise value.with_traceback(tb)\n  File \"/venv/lib/python3.6/site-packages/gevent/threadpool.py\", line 281, in _worker\n    value = func(*args, **kwargs)\nsocket.herror: [Errno 1] Unknown host\n\nDuring handling of the above exception, another exception occurred:\n\nTraceback (most recent call last):\n  File \"/venv/lib/python3.6/site-packages/django/core/handlers/exception.py\", line 34, in inner\n    response = get_response(request)\n  File \"/venv/lib/python3.6/site-packages/django/core/handlers/base.py\", line 126, in _get_response\n    response = self.process_exception_by_middleware(e, request)\n  File \"/venv/lib/python3.6/site-packages/django/core/handlers/base.py\", line 124, in _get_response\n    response = wrapped_callback(request, *callback_args, **callback_kwargs)\n  File \"/venv/lib/python3.6/site-packages/django/views/decorators/csrf.py\", line 54, in wrapped_view\n    return view_func(*args, **kwargs)\n  File \"/venv/lib/python3.6/site-packages/django/views/generic/base.py\", line 68, in view\n    return self.dispatch(request, *args, **kwargs)\n  File \"/venv/lib/python3.6/site-packages/rest_framework/views.py\", line 483, in dispatch\n    response = self.handle_exception(exc)\n  File \"/venv/lib/python3.6/site-packages/rest_framework/views.py\", line 443, in handle_exception\n    self.raise_uncaught_exception(exc)\n  File \"/venv/lib/python3.6/site-packages/rest_framework/views.py\", line 480, in dispatch\n    response = handler(request, *args, **kwargs)\n  File \"/code/api/views.py\", line 24, in post\n    input_entered\n  File \"/code/api/utils.py\", line 54, in validate_input\n    json_contains_ip_address = self.validate_ip_address(input)\n  File \"/code/api/utils.py\", line 78, in validate_ip_address\n    return {'domain':self.get_reverse_dns(ip_address),\n  File \"/code/api/utils.py\", line 132, in get_reverse_dns\n    reverse_dns = socket.gethostbyaddr(ip_address)[0]\n  File \"/venv/lib/python3.6/site-packages/gevent/_socketcommon.py\", line 222, in gethostbyaddr\n    return get_hub().resolver.gethostbyaddr(ip_address)\n  File \"/venv/lib/python3.6/site-packages/gevent/resolver/thread.py\", line 68, in gethostbyaddr\n    return self.pool.apply(_socket.gethostbyaddr, args, kwargs)\n  File \"/venv/lib/python3.6/site-packages/gevent/pool.py\", line 159, in apply\n    return self.spawn(func, *args, **kwds).get()\n  File \"src/gevent/event.py\", line 381, in gevent._event.AsyncResult.get\n  File \"src/gevent/event.py\", line 409, in gevent._event.AsyncResult.get\n  File \"src/gevent/event.py\", line 399, in gevent._event.AsyncResult.get\n  File \"src/gevent/event.py\", line 379, in gevent._event.AsyncResult._raise_exception\n  File \"/venv/lib/python3.6/site-packages/gevent/_compat.py\", line 47, in reraise\n    raise value.with_traceback(tb)\n  File \"/venv/lib/python3.6/site-packages/gevent/threadpool.py\", line 281, in _worker\n    value = func(*args, **kwargs)\nsocket.gaierror: [Errno -2] Name or service not known", "status_code": 500, "request": "<WSGIRequest: POST '/api/'>"}
{"message": "Method Not Allowed: /api/", "status_code": 405, "request": "<WSGIRequest: GET '/api/'>"}
{"message": "Method Not Allowed: /api/", "status_code": 405, "request": "<WSGIRequest: GET '/api/'>"}
{"message": "Internal Server Error: /api/", "exc_info": "Traceback (most recent call last):\n  File \"/code/api/utils.py\", line 130, in get_reverse_dns\n    reverse_dns = socket.gethostbyaddr(ip_address)[0]\n  File \"/venv/lib/python3.6/site-packages/gevent/_socketcommon.py\", line 222, in gethostbyaddr\n    return get_hub().resolver.gethostbyaddr(ip_address)\n  File \"/venv/lib/python3.6/site-packages/gevent/resolver/thread.py\", line 68, in gethostbyaddr\n    return self.pool.apply(_socket.gethostbyaddr, args, kwargs)\n  File \"/venv/lib/python3.6/site-packages/gevent/pool.py\", line 159, in apply\n    return self.spawn(func, *args, **kwds).get()\n  File \"src/gevent/event.py\", line 381, in gevent._event.AsyncResult.get\n  File \"src/gevent/event.py\", line 409, in gevent._event.AsyncResult.get\n  File \"src/gevent/event.py\", line 399, in gevent._event.AsyncResult.get\n  File \"src/gevent/event.py\", line 379, in gevent._event.AsyncResult._raise_exception\n  File \"/venv/lib/python3.6/site-packages/gevent/_compat.py\", line 47, in reraise\n    raise value.with_traceback(tb)\n  File \"/venv/lib/python3.6/site-packages/gevent/threadpool.py\", line 281, in _worker\n    value = func(*args, **kwargs)\nsocket.herror: [Errno 1] Unknown host\n\nDuring handling of the above exception, another exception occurred:\n\nTraceback (most recent call last):\n  File \"/code/api/utils.py\", line 134, in get_reverse_dns\n    reverse_dns = socket.gethostbyaddr(ip_address)[0]\n  File \"/venv/lib/python3.6/site-packages/gevent/_socketcommon.py\", line 222, in gethostbyaddr\n    return get_hub().resolver.gethostbyaddr(ip_address)\n  File \"/venv/lib/python3.6/site-packages/gevent/resolver/thread.py\", line 68, in gethostbyaddr\n    return self.pool.apply(_socket.gethostbyaddr, args, kwargs)\n  File \"/venv/lib/python3.6/site-packages/gevent/pool.py\", line 159, in apply\n    return self.spawn(func, *args, **kwds).get()\n  File \"src/gevent/event.py\", line 381, in gevent._event.AsyncResult.get\n  File \"src/gevent/event.py\", line 409, in gevent._event.AsyncResult.get\n  File \"src/gevent/event.py\", line 399, in gevent._event.AsyncResult.get\n  File \"src/gevent/event.py\", line 379, in gevent._event.AsyncResult._raise_exception\n  File \"/venv/lib/python3.6/site-packages/gevent/_compat.py\", line 47, in reraise\n    raise value.with_traceback(tb)\n  File \"/venv/lib/python3.6/site-packages/gevent/threadpool.py\", line 281, in _worker\n    value = func(*args, **kwargs)\nsocket.gaierror: [Errno -2] Name or service not known\n\nDuring handling of the above exception, another exception occurred:\n\nTraceback (most recent call last):\n  File \"/venv/lib/python3.6/site-packages/django/core/handlers/exception.py\", line 34, in inner\n    response = get_response(request)\n  File \"/venv/lib/python3.6/site-packages/django/core/handlers/base.py\", line 126, in _get_response\n    response = self.process_exception_by_middleware(e, request)\n  File \"/venv/lib/python3.6/site-packages/django/core/handlers/base.py\", line 124, in _get_response\n    response = wrapped_callback(request, *callback_args, **callback_kwargs)\n  File \"/venv/lib/python3.6/site-packages/django/views/decorators/csrf.py\", line 54, in wrapped_view\n    return view_func(*args, **kwargs)\n  File \"/venv/lib/python3.6/site-packages/django/views/generic/base.py\", line 68, in view\n    return self.dispatch(request, *args, **kwargs)\n  File \"/venv/lib/python3.6/site-packages/rest_framework/views.py\", line 483, in dispatch\n    response = self.handle_exception(exc)\n  File \"/venv/lib/python3.6/site-packages/rest_framework/views.py\", line 443, in handle_exception\n    self.raise_uncaught_exception(exc)\n  File \"/venv/lib/python3.6/site-packages/rest_framework/views.py\", line 480, in dispatch\n    response = handler(request, *args, **kwargs)\n  File \"/code/api/views.py\", line 24, in post\n    input_entered\n  File \"/code/api/utils.py\", line 64, in validate_input\n    return self.validate_domain(input)\n  File \"/code/api/utils.py\", line 121, in validate_domain\n    \"reverse_dns\": self.get_reverse_dns(ip_address)\n  File \"/code/api/utils.py\", line 136, in get_reverse_dns\n    answers = dns.resolver.query(ip_address, 'CNAME')\nNameError: name 'dns' is not defined", "status_code": 500, "request": "<WSGIRequest: POST '/api/'>"}
{"message": "Method Not Allowed: /api/", "status_code": 405, "request": "<WSGIRequest: GET '/api/'>"}
{"message": "Internal Server Error: /api/", "exc_info": "Traceback (most recent call last):\n  File \"/code/api/utils.py\", line 130, in get_reverse_dns\n    reverse_dns = socket.gethostbyaddr(ip_address)[0]\n  File \"/venv/lib/python3.6/site-packages/gevent/_socketcommon.py\", line 222, in gethostbyaddr\n    return get_hub().resolver.gethostbyaddr(ip_address)\n  File \"/venv/lib/python3.6/site-packages/gevent/resolver/thread.py\", line 68, in gethostbyaddr\n    return self.pool.apply(_socket.gethostbyaddr, args, kwargs)\n  File \"/venv/lib/python3.6/site-packages/gevent/pool.py\", line 159, in apply\n    return self.spawn(func, *args, **kwds).get()\n  File \"src/gevent/event.py\", line 381, in gevent._event.AsyncResult.get\n  File \"src/gevent/event.py\", line 409, in gevent._event.AsyncResult.get\n  File \"src/gevent/event.py\", line 399, in gevent._event.AsyncResult.get\n  File \"src/gevent/event.py\", line 379, in gevent._event.AsyncResult._raise_exception\n  File \"/venv/lib/python3.6/site-packages/gevent/_compat.py\", line 47, in reraise\n    raise value.with_traceback(tb)\n  File \"/venv/lib/python3.6/site-packages/gevent/threadpool.py\", line 281, in _worker\n    value = func(*args, **kwargs)\nsocket.herror: [Errno 1] Unknown host\n\nDuring handling of the above exception, another exception occurred:\n\nTraceback (most recent call last):\n  File \"/code/api/utils.py\", line 134, in get_reverse_dns\n    reverse_dns = socket.gethostbyaddr(ip_address)[0]\n  File \"/venv/lib/python3.6/site-packages/gevent/_socketcommon.py\", line 222, in gethostbyaddr\n    return get_hub().resolver.gethostbyaddr(ip_address)\n  File \"/venv/lib/python3.6/site-packages/gevent/resolver/thread.py\", line 68, in gethostbyaddr\n    return self.pool.apply(_socket.gethostbyaddr, args, kwargs)\n  File \"/venv/lib/python3.6/site-packages/gevent/pool.py\", line 159, in apply\n    return self.spawn(func, *args, **kwds).get()\n  File \"src/gevent/event.py\", line 381, in gevent._event.AsyncResult.get\n  File \"src/gevent/event.py\", line 409, in gevent._event.AsyncResult.get\n  File \"src/gevent/event.py\", line 399, in gevent._event.AsyncResult.get\n  File \"src/gevent/event.py\", line 379, in gevent._event.AsyncResult._raise_exception\n  File \"/venv/lib/python3.6/site-packages/gevent/_compat.py\", line 47, in reraise\n    raise value.with_traceback(tb)\n  File \"/venv/lib/python3.6/site-packages/gevent/threadpool.py\", line 281, in _worker\n    value = func(*args, **kwargs)\nsocket.gaierror: [Errno -2] Name or service not known\n\nDuring handling of the above exception, another exception occurred:\n\nTraceback (most recent call last):\n  File \"/venv/lib/python3.6/site-packages/django/core/handlers/exception.py\", line 34, in inner\n    response = get_response(request)\n  File \"/venv/lib/python3.6/site-packages/django/core/handlers/base.py\", line 126, in _get_response\n    response = self.process_exception_by_middleware(e, request)\n  File \"/venv/lib/python3.6/site-packages/django/core/handlers/base.py\", line 124, in _get_response\n    response = wrapped_callback(request, *callback_args, **callback_kwargs)\n  File \"/venv/lib/python3.6/site-packages/django/views/decorators/csrf.py\", line 54, in wrapped_view\n    return view_func(*args, **kwargs)\n  File \"/venv/lib/python3.6/site-packages/django/views/generic/base.py\", line 68, in view\n    return self.dispatch(request, *args, **kwargs)\n  File \"/venv/lib/python3.6/site-packages/rest_framework/views.py\", line 483, in dispatch\n    response = self.handle_exception(exc)\n  File \"/venv/lib/python3.6/site-packages/rest_framework/views.py\", line 443, in handle_exception\n    self.raise_uncaught_exception(exc)\n  File \"/venv/lib/python3.6/site-packages/rest_framework/views.py\", line 480, in dispatch\n    response = handler(request, *args, **kwargs)\n  File \"/code/api/views.py\", line 25, in post\n    input_entered\n  File \"/code/api/utils.py\", line 55, in validate_input\n    json_contains_ip_address = self.validate_ip_address(input)\n  File \"/code/api/utils.py\", line 79, in validate_ip_address\n    return {'domain':self.get_reverse_dns(ip_address),\n  File \"/code/api/utils.py\", line 136, in get_reverse_dns\n    answers = dns.resolver.query(ip_address, 'CNAME')\nNameError: name 'dns' is not defined", "status_code": 500, "request": "<WSGIRequest: POST '/api/'>"}
{"message": "Method Not Allowed: /api/", "status_code": 405, "request": "<WSGIRequest: GET '/api/'>"}
{"message": "Internal Server Error: /api/", "exc_info": "Traceback (most recent call last):\n  File \"/code/api/utils.py\", line 130, in get_reverse_dns\n    reverse_dns = socket.gethostbyaddr(ip_address)[0]\n  File \"/venv/lib/python3.6/site-packages/gevent/_socketcommon.py\", line 222, in gethostbyaddr\n    return get_hub().resolver.gethostbyaddr(ip_address)\n  File \"/venv/lib/python3.6/site-packages/gevent/resolver/thread.py\", line 68, in gethostbyaddr\n    return self.pool.apply(_socket.gethostbyaddr, args, kwargs)\n  File \"/venv/lib/python3.6/site-packages/gevent/pool.py\", line 159, in apply\n    return self.spawn(func, *args, **kwds).get()\n  File \"src/gevent/event.py\", line 381, in gevent._event.AsyncResult.get\n  File \"src/gevent/event.py\", line 409, in gevent._event.AsyncResult.get\n  File \"src/gevent/event.py\", line 399, in gevent._event.AsyncResult.get\n  File \"src/gevent/event.py\", line 379, in gevent._event.AsyncResult._raise_exception\n  File \"/venv/lib/python3.6/site-packages/gevent/_compat.py\", line 47, in reraise\n    raise value.with_traceback(tb)\n  File \"/venv/lib/python3.6/site-packages/gevent/threadpool.py\", line 281, in _worker\n    value = func(*args, **kwargs)\nsocket.herror: [Errno 1] Unknown host\n\nDuring handling of the above exception, another exception occurred:\n\nTraceback (most recent call last):\n  File \"/code/api/utils.py\", line 134, in get_reverse_dns\n    reverse_dns = socket.gethostbyaddr(ip_address)[0]\n  File \"/venv/lib/python3.6/site-packages/gevent/_socketcommon.py\", line 222, in gethostbyaddr\n    return get_hub().resolver.gethostbyaddr(ip_address)\n  File \"/venv/lib/python3.6/site-packages/gevent/resolver/thread.py\", line 68, in gethostbyaddr\n    return self.pool.apply(_socket.gethostbyaddr, args, kwargs)\n  File \"/venv/lib/python3.6/site-packages/gevent/pool.py\", line 159, in apply\n    return self.spawn(func, *args, **kwds).get()\n  File \"src/gevent/event.py\", line 381, in gevent._event.AsyncResult.get\n  File \"src/gevent/event.py\", line 409, in gevent._event.AsyncResult.get\n  File \"src/gevent/event.py\", line 399, in gevent._event.AsyncResult.get\n  File \"src/gevent/event.py\", line 379, in gevent._event.AsyncResult._raise_exception\n  File \"/venv/lib/python3.6/site-packages/gevent/_compat.py\", line 47, in reraise\n    raise value.with_traceback(tb)\n  File \"/venv/lib/python3.6/site-packages/gevent/threadpool.py\", line 281, in _worker\n    value = func(*args, **kwargs)\nsocket.gaierror: [Errno -2] Name or service not known\n\nDuring handling of the above exception, another exception occurred:\n\nTraceback (most recent call last):\n  File \"/venv/lib/python3.6/site-packages/django/core/handlers/exception.py\", line 34, in inner\n    response = get_response(request)\n  File \"/venv/lib/python3.6/site-packages/django/core/handlers/base.py\", line 126, in _get_response\n    response = self.process_exception_by_middleware(e, request)\n  File \"/venv/lib/python3.6/site-packages/django/core/handlers/base.py\", line 124, in _get_response\n    response = wrapped_callback(request, *callback_args, **callback_kwargs)\n  File \"/venv/lib/python3.6/site-packages/django/views/decorators/csrf.py\", line 54, in wrapped_view\n    return view_func(*args, **kwargs)\n  File \"/venv/lib/python3.6/site-packages/django/views/generic/base.py\", line 68, in view\n    return self.dispatch(request, *args, **kwargs)\n  File \"/venv/lib/python3.6/site-packages/rest_framework/views.py\", line 483, in dispatch\n    response = self.handle_exception(exc)\n  File \"/venv/lib/python3.6/site-packages/rest_framework/views.py\", line 443, in handle_exception\n    self.raise_uncaught_exception(exc)\n  File \"/venv/lib/python3.6/site-packages/rest_framework/views.py\", line 480, in dispatch\n    response = handler(request, *args, **kwargs)\n  File \"/code/api/views.py\", line 25, in post\n    input_entered\n  File \"/code/api/utils.py\", line 55, in validate_input\n    json_contains_ip_address = self.validate_ip_address(input)\n  File \"/code/api/utils.py\", line 79, in validate_ip_address\n    return {'domain':self.get_reverse_dns(ip_address),\n  File \"/code/api/utils.py\", line 136, in get_reverse_dns\n    answers = dns.resolver.query(ip_address, 'CNAME')\nNameError: name 'dns' is not defined", "status_code": 500, "request": "<WSGIRequest: POST '/api/'>"}
{"message": "Method Not Allowed: /api/", "status_code": 405, "request": "<WSGIRequest: GET '/api/'>"}
{"message": "Internal Server Error: /api/", "exc_info": "Traceback (most recent call last):\n  File \"/code/api/utils.py\", line 130, in get_reverse_dns\n    reverse_dns = socket.gethostbyaddr(ip_address)[0]\n  File \"/venv/lib/python3.6/site-packages/gevent/_socketcommon.py\", line 222, in gethostbyaddr\n    return get_hub().resolver.gethostbyaddr(ip_address)\n  File \"/venv/lib/python3.6/site-packages/gevent/resolver/thread.py\", line 68, in gethostbyaddr\n    return self.pool.apply(_socket.gethostbyaddr, args, kwargs)\n  File \"/venv/lib/python3.6/site-packages/gevent/pool.py\", line 159, in apply\n    return self.spawn(func, *args, **kwds).get()\n  File \"src/gevent/event.py\", line 381, in gevent._event.AsyncResult.get\n  File \"src/gevent/event.py\", line 409, in gevent._event.AsyncResult.get\n  File \"src/gevent/event.py\", line 399, in gevent._event.AsyncResult.get\n  File \"src/gevent/event.py\", line 379, in gevent._event.AsyncResult._raise_exception\n  File \"/venv/lib/python3.6/site-packages/gevent/_compat.py\", line 47, in reraise\n    raise value.with_traceback(tb)\n  File \"/venv/lib/python3.6/site-packages/gevent/threadpool.py\", line 281, in _worker\n    value = func(*args, **kwargs)\nsocket.herror: [Errno 1] Unknown host\n\nDuring handling of the above exception, another exception occurred:\n\nTraceback (most recent call last):\n  File \"/code/api/utils.py\", line 134, in get_reverse_dns\n    reverse_dns = socket.gethostbyaddr(ip_address)[0]\n  File \"/venv/lib/python3.6/site-packages/gevent/_socketcommon.py\", line 222, in gethostbyaddr\n    return get_hub().resolver.gethostbyaddr(ip_address)\n  File \"/venv/lib/python3.6/site-packages/gevent/resolver/thread.py\", line 68, in gethostbyaddr\n    return self.pool.apply(_socket.gethostbyaddr, args, kwargs)\n  File \"/venv/lib/python3.6/site-packages/gevent/pool.py\", line 159, in apply\n    return self.spawn(func, *args, **kwds).get()\n  File \"src/gevent/event.py\", line 381, in gevent._event.AsyncResult.get\n  File \"src/gevent/event.py\", line 409, in gevent._event.AsyncResult.get\n  File \"src/gevent/event.py\", line 399, in gevent._event.AsyncResult.get\n  File \"src/gevent/event.py\", line 379, in gevent._event.AsyncResult._raise_exception\n  File \"/venv/lib/python3.6/site-packages/gevent/_compat.py\", line 47, in reraise\n    raise value.with_traceback(tb)\n  File \"/venv/lib/python3.6/site-packages/gevent/threadpool.py\", line 281, in _worker\n    value = func(*args, **kwargs)\nsocket.gaierror: [Errno -2] Name or service not known\n\nDuring handling of the above exception, another exception occurred:\n\nTraceback (most recent call last):\n  File \"/venv/lib/python3.6/site-packages/django/core/handlers/exception.py\", line 34, in inner\n    response = get_response(request)\n  File \"/venv/lib/python3.6/site-packages/django/core/handlers/base.py\", line 126, in _get_response\n    response = self.process_exception_by_middleware(e, request)\n  File \"/venv/lib/python3.6/site-packages/django/core/handlers/base.py\", line 124, in _get_response\n    response = wrapped_callback(request, *callback_args, **callback_kwargs)\n  File \"/venv/lib/python3.6/site-packages/django/views/decorators/csrf.py\", line 54, in wrapped_view\n    return view_func(*args, **kwargs)\n  File \"/venv/lib/python3.6/site-packages/django/views/generic/base.py\", line 68, in view\n    return self.dispatch(request, *args, **kwargs)\n  File \"/venv/lib/python3.6/site-packages/rest_framework/views.py\", line 483, in dispatch\n    response = self.handle_exception(exc)\n  File \"/venv/lib/python3.6/site-packages/rest_framework/views.py\", line 443, in handle_exception\n    self.raise_uncaught_exception(exc)\n  File \"/venv/lib/python3.6/site-packages/rest_framework/views.py\", line 480, in dispatch\n    response = handler(request, *args, **kwargs)\n  File \"/code/api/views.py\", line 25, in post\n    input_entered\n  File \"/code/api/utils.py\", line 55, in validate_input\n    json_contains_ip_address = self.validate_ip_address(input)\n  File \"/code/api/utils.py\", line 79, in validate_ip_address\n    return {'domain':self.get_reverse_dns(ip_address),\n  File \"/code/api/utils.py\", line 136, in get_reverse_dns\n    answers = dns.resolver.query(ip_address, 'CNAME')\n  File \"/venv/lib/python3.6/site-packages/dns/resolver.py\", line 1132, in query\n    raise_on_no_answer, source_port)\n  File \"/venv/lib/python3.6/site-packages/dns/resolver.py\", line 1051, in query\n    raise NXDOMAIN(qnames=qnames_to_try, responses=nxdomain_responses)\ndns.resolver.NXDOMAIN: The DNS query name does not exist: 172.217.197.17.in-addr.arpa.", "status_code": 500, "request": "<WSGIRequest: POST '/api/'>"}
{"message": "Method Not Allowed: /api/", "status_code": 405, "request": "<WSGIRequest: GET '/api/'>"}
{"message": "Method Not Allowed: /api/", "status_code": 405, "request": "<WSGIRequest: GET '/api/'>"}
{"message": "Internal Server Error: /api/", "exc_info": "Traceback (most recent call last):\n  File \"/venv/lib/python3.6/site-packages/django/core/handlers/exception.py\", line 34, in inner\n    response = get_response(request)\n  File \"/venv/lib/python3.6/site-packages/django/core/handlers/base.py\", line 126, in _get_response\n    response = self.process_exception_by_middleware(e, request)\n  File \"/venv/lib/python3.6/site-packages/django/core/handlers/base.py\", line 124, in _get_response\n    response = wrapped_callback(request, *callback_args, **callback_kwargs)\n  File \"/venv/lib/python3.6/site-packages/django/views/decorators/csrf.py\", line 54, in wrapped_view\n    return view_func(*args, **kwargs)\n  File \"/venv/lib/python3.6/site-packages/django/views/generic/base.py\", line 68, in view\n    return self.dispatch(request, *args, **kwargs)\n  File \"/venv/lib/python3.6/site-packages/rest_framework/views.py\", line 483, in dispatch\n    response = self.handle_exception(exc)\n  File \"/venv/lib/python3.6/site-packages/rest_framework/views.py\", line 443, in handle_exception\n    self.raise_uncaught_exception(exc)\n  File \"/venv/lib/python3.6/site-packages/rest_framework/views.py\", line 480, in dispatch\n    response = handler(request, *args, **kwargs)\n  File \"/code/api/views.py\", line 37, in post\n    port_scanner = masscan.PortScanner()\n  File \"/venv/lib/python3.6/site-packages/masscan/masscan.py\", line 132, in __init__\n    'masscan program was not found in path. PATH is : {0}'.format(os.getenv('PATH'))\nmasscan.masscan.PortScannerError: 'masscan program was not found in path. PATH is : /venv/bin:/bin:/usr/bin:/usr/local/bin'", "status_code": 500, "request": "<WSGIRequest: POST '/api/'>"}
{"message": "Not Found: /favicon.ico", "status_code": 404, "request": "<WSGIRequest: GET '/favicon.ico'>"}
{"message": "Not Found: /", "status_code": 404, "request": "<WSGIRequest: GET '/'>"}
{"message": "Method Not Allowed: /api/", "status_code": 405, "request": "<WSGIRequest: GET '/api/'>"}
{"message": "Not Found: /", "status_code": 404, "request": "<WSGIRequest: GET '/'>"}
{"message": "Not Found: /accounts/login/", "status_code": 404, "request": "<WSGIRequest: GET '/accounts/login/?next=/swagger/'>"}
{"message": "Method Not Allowed: /api/", "status_code": 405, "request": "<WSGIRequest: GET '/api/'>"}
{"message": "Bad Request: /api/", "status_code": 400, "request": "<WSGIRequest: POST '/api/'>"}
{"message": "Bad Request: /api/", "status_code": 400, "request": "<WSGIRequest: POST '/api/'>"}
{"message": "Method Not Allowed: /api/", "status_code": 405, "request": "<WSGIRequest: GET '/api/'>"}
{"message": "Method Not Allowed: /api/", "status_code": 405, "request": "<WSGIRequest: GET '/api/'>"}
